<mujoco>
  <compiler meshdir="./mesh"/>
  <worldbody>
      <geom name="floor" size="0 0 .05" type="plane" material="grid" condim="3"/>
    <body name="Back_1" pos="-0.03638419508934021 0.32031768560409546 0.75876384973526">
    <joint type="free"/>
    <geom type="capsule" name="Back_1_geom" size="0.05" fromto="0 0 0 0.0 -0.07109183073043823 -0.09252709150314331"/>
      <body name="Back_2" pos="0.0 -0.07109183073043823 -0.09252709150314331">
      <joint type="hinge" name="rx_Back_2" axis="1 0 0" range="-9.99999970909292 9.99999970909292"/>
      <joint type="hinge" name="ry_Back_2" axis="0 1 0" range="-4.99999985454646 4.99999985454646"/>
      <joint type="hinge" name="rz_Back_2" axis="0 0 1" range="-9.99999970909292 6.000000166965211"/>
      <geom type="capsule" name="Back_2_geom" size="0.05" fromto="0 0 0 0.0 -0.2740018367767334 0.09516853094100952"/>
        <body name="Back_3" pos="0.0 -0.2740018367767334 0.09516853094100952">
        <joint type="hinge" name="rx_Back_3" axis="1 0 0" range="-9.99999970909292 9.99999970909292"/>
        <joint type="hinge" name="ry_Back_3" axis="0 1 0" range="-4.99999985454646 4.99999985454646"/>
        <joint type="hinge" name="rz_Back_3" axis="0 0 1" range="-9.99999970909292 6.000000166965211"/>
        <geom type="capsule" name="Back_3_geom" size="0.05" fromto="0 0 0 0.0 -0.2097725123167038 0.021728336811065674"/>
          <body name="Back_4" pos="0.0 -0.2097725123167038 0.021728336811065674">
          <joint type="hinge" name="rx_Back_4" axis="1 0 0" range="-9.99999970909292 9.99999970909292"/>
          <joint type="hinge" name="ry_Back_4" axis="0 1 0" range="-4.99999985454646 4.99999985454646"/>
          <joint type="hinge" name="rz_Back_4" axis="0 0 1" range="-9.99999970909292 6.000000166965211"/>
          <geom type="capsule" name="Back_4_geom" size="0.05" fromto="0 0 0 0.0 -0.2558934688568115 -0.008959829807281494"/>
            <body name="Back_5" pos="0.0 -0.2558934688568115 -0.008959829807281494">
            <joint type="hinge" name="rx_Back_5" axis="1 0 0" range="-9.99999970909292 9.99999970909292"/>
            <joint type="hinge" name="ry_Back_5" axis="0 1 0" range="-4.99999985454646 4.99999985454646"/>
            <joint type="hinge" name="rz_Back_5" axis="0 0 1" range="-9.99999970909292 6.000000166965211"/>
            <geom type="capsule" name="Back_5_geom" size="0.05" fromto="0 0 0 0.0 -0.2308562994003296 -0.08291542530059814"/>
              <body name="Back_6" pos="0.0 -0.2308562994003296 -0.08291542530059814">
              <joint type="hinge" name="rx_Back_6" axis="1 0 0" range="-9.99999970909292 9.99999970909292"/>
              <joint type="hinge" name="ry_Back_6" axis="0 1 0" range="-4.99999985454646 4.99999985454646"/>
              <joint type="hinge" name="rz_Back_6" axis="0 0 1" range="-9.99999970909292 6.000000166965211"/>
              <geom type="capsule" name="Back_6_geom" size="0.05" fromto="0 0 0 0.0 -0.2347009778022766 -0.07146763801574707"/>
                <body name="Neck" pos="0.0 -0.2347009778022766 -0.07146763801574707">
                <geom type="capsule" name="Neck_geom" size="0.05" fromto="0 0 0 0.0 -0.18661510944366455 0.0330730676651001"/>
                  <body name="Head" pos="0.0 -0.18661510944366455 0.0330730676651001">
                  <geom type="capsule" name="Head_geom" size="0.05" fromto="0 0 0 -0.003004610538482666 -0.18622291088104248 -0.011018574237823486"/>
                    <body name="L_Ear_1" pos="-0.003004610538482666 -0.18622291088104248 -0.011018574237823486">
                    <geom type="capsule" name="L_Ear_1_geom" size="0.05" fromto="0 0 0 0.0987759679555893 0.10522949695587158 0.02556777000427246"/>
                      <body name="L_Ear_2" pos="0.0987759679555893 0.10522949695587158 0.02556777000427246">
                      <geom type="capsule" name="L_Ear_2_geom" size="0.05" fromto="0 0 0 0.1209292858839035 0.06745660305023193 0.010155320167541504"/>
                        <body name="L_Ear_3" pos="0.1209292858839035 0.06745660305023193 0.010155320167541504">
                        <geom type="capsule" name="L_Ear_3_geom" size="0.05" fromto="0 0 0 0.04588824510574341 0.02377474308013916 0.02690833806991577"/>
                        </body>
                      </body>
                    </body>
                    <body name="Jaw_1" pos="-0.003004610538482666 -0.18622291088104248 -0.011018574237823486">
                    <geom type="capsule" name="Jaw_1_geom" size="0.05" fromto="0 0 0 0.003004617989063263 -0.12477743625640869 -0.27392762899398804"/>
                      <body name="Jaw_2" pos="0.003004617989063263 -0.12477743625640869 -0.27392762899398804">
                      <geom type="capsule" name="Jaw_2_geom" size="0.05" fromto="0 0 0 0.002912815660238266 -0.13363254070281982 -0.01868879795074463"/>
                      </body>
                    </body>
                    <body name="R_Ear_1" pos="-0.003004610538482666 -0.18622291088104248 -0.011018574237823486">
                    <geom type="capsule" name="R_Ear_1_geom" size="0.05" fromto="0 0 0 -0.09276671707630157 0.10522949695587158 0.02556777000427246"/>
                      <body name="R_Ear_2" pos="-0.09276671707630157 0.10522949695587158 0.02556777000427246">
                      <geom type="capsule" name="R_Ear_2_geom" size="0.05" fromto="0 0 0 -0.12092931568622589 0.06745660305023193 0.010155320167541504"/>
                        <body name="R_Ear_3" pos="-0.12092931568622589 0.06745660305023193 0.010155320167541504">
                        <geom type="capsule" name="R_Ear_3_geom" size="0.05" fromto="0 0 0 -0.04588821530342102 0.02377474308013916 0.02690833806991577"/>
                        </body>
                      </body>
                    </body>
                    <body name="Nose" pos="-0.003004610538482666 -0.18622291088104248 -0.011018574237823486">
                    <geom type="capsule" name="Nose_geom" size="0.05" fromto="0 0 0 7.450580596923828e-09 -0.3301737308502197 -0.12187623977661133"/>
                    </body>
                  </body>
                </body>
                <body name="L_F_Paw_1" pos="0.0 -0.2347009778022766 -0.07146763801574707">
                <joint type="hinge" name="rx_L_F_Paw_1" axis="1 0 0" range="-30.000000834826057 30.000000834826057"/>
                <joint type="hinge" name="ry_L_F_Paw_1" axis="0 1 0" range="-19.99999941818584 19.99999941818584"/>
                <joint type="hinge" name="rz_L_F_Paw_1" axis="0 0 1" range="-30.000000834826057 30.000000834826057"/>
                <geom type="capsule" name="L_F_Paw_1_geom" size="0.05" fromto="0 0 0 0.17953817546367645 0.16833937168121338 -0.06021338701248169"/>
                  <body name="L_F_Paw_2" pos="0.17953817546367645 0.16833937168121338 -0.06021338701248169">
                  <joint type="hinge" name="rx_L_F_Paw_2" axis="1 0 0" range="-9.99999970909292 9.99999970909292"/>
                  <joint type="hinge" name="rz_L_F_Paw_2" axis="0 0 1" range="-45.00000125223908 45.00000125223908"/>
                  <geom type="capsule" name="L_F_Paw_2_geom" size="0.05" fromto="0 0 0 -0.014132246375083923 -0.039042651653289795 -0.34415319561958313"/>
                    <body name="L_F_Paw_3" pos="-0.014132246375083923 -0.039042651653289795 -0.34415319561958313">
                    <geom type="capsule" name="L_F_Paw_3_geom" size="0.05" fromto="0 0 0 -0.021816067397594452 -0.09817075729370117 -0.17515115439891815"/>
                      <body name="L_F_Finger_2_1" pos="-0.021816067397594452 -0.09817075729370117 -0.17515115439891815">
                      <geom type="capsule" name="L_F_Finger_2_1_geom" size="0.05" fromto="0 0 0 -0.0023449286818504333 -0.0585518479347229 -0.01007068157196045"/>
                        <body name="L_F_Finger_2_2" pos="-0.0023449286818504333 -0.0585518479347229 -0.01007068157196045">
                        <geom type="capsule" name="L_F_Finger_2_2_geom" size="0.05" fromto="0 0 0 -0.0031607970595359802 -0.054094552993774414 -0.013577751815319061"/>
                          <body name="L_F_Finger_2_3" pos="-0.0031607970595359802 -0.054094552993774414 -0.013577751815319061">
                          <geom type="capsule" name="L_F_Finger_2_3_geom" size="0.05" fromto="0 0 0 -0.0014780685305595398 -0.0357135534286499 -0.015574152581393719"/>
                          </body>
                        </body>
                      </body>
                      <body name="L_F_Finger_3_1" pos="-0.021816067397594452 -0.09817075729370117 -0.17515115439891815">
                      <geom type="capsule" name="L_F_Finger_3_1_geom" size="0.05" fromto="0 0 0 0.028311945497989655 -0.05318993330001831 -0.006568755954504013"/>
                        <body name="L_F_Finger_3_2" pos="0.028311945497989655 -0.05318993330001831 -0.006568755954504013">
                        <geom type="capsule" name="L_F_Finger_3_2_geom" size="0.05" fromto="0 0 0 0.018212109804153442 -0.04630088806152344 -0.007779568433761597"/>
                          <body name="L_F_Finger_3_3" pos="0.018212109804153442 -0.04630088806152344 -0.007779568433761597">
                          <geom type="capsule" name="L_F_Finger_3_3_geom" size="0.05" fromto="0 0 0 0.013797968626022339 -0.03786897659301758 -0.011330218985676765"/>
                          </body>
                        </body>
                      </body>
                      <body name="L_F_Finger_4_1" pos="-0.021816067397594452 -0.09817075729370117 -0.17515115439891815">
                      <geom type="capsule" name="L_F_Finger_4_1_geom" size="0.05" fromto="0 0 0 0.04633777588605881 -0.029399394989013672 -0.027229392901062965"/>
                        <body name="L_F_Finger_4_2" pos="0.04633777588605881 -0.029399394989013672 -0.027229392901062965">
                        <geom type="capsule" name="L_F_Finger_4_2_geom" size="0.05" fromto="0 0 0 0.025139257311820984 -0.022921383380889893 -0.0033581219613552094"/>
                          <body name="L_F_Finger_4_3" pos="0.025139257311820984 -0.022921383380889893 -0.0033581219613552094">
                          <geom type="capsule" name="L_F_Finger_4_3_geom" size="0.05" fromto="0 0 0 0.020379766821861267 -0.018852174282073975 -0.010923106223344803"/>
                          </body>
                        </body>
                      </body>
                      <body name="L_F_Finger_1_1" pos="-0.021816067397594452 -0.09817075729370117 -0.17515115439891815">
                      <geom type="capsule" name="L_F_Finger_1_1_geom" size="0.05" fromto="0 0 0 -0.03131963312625885 -0.041713058948516846 -0.024164240807294846"/>
                        <body name="L_F_Finger_1_2" pos="-0.03131963312625885 -0.041713058948516846 -0.024164240807294846">
                        <geom type="capsule" name="L_F_Finger_1_2_geom" size="0.05" fromto="0 0 0 -0.026167742908000946 -0.03220933675765991 3.284960985183716e-05"/>
                          <body name="L_F_Finger_1_3" pos="-0.026167742908000946 -0.03220933675765991 3.284960985183716e-05">
                          <geom type="capsule" name="L_F_Finger_1_3_geom" size="0.05" fromto="0 0 0 -0.01939430646598339 -0.02483123540878296 -0.01097293384373188"/>
                          </body>
                        </body>
                      </body>
                    </body>
                  </body>
                </body>
                <body name="R_F_Paw_1" pos="0.0 -0.2347009778022766 -0.07146763801574707">
                <joint type="hinge" name="rx_R_F_Paw_1" axis="1 0 0" range="-30.000000834826057 30.000000834826057"/>
                <joint type="hinge" name="ry_R_F_Paw_1" axis="0 1 0" range="-19.99999941818584 19.99999941818584"/>
                <joint type="hinge" name="rz_R_F_Paw_1" axis="0 0 1" range="-30.000000834826057 30.000000834826057"/>
                <geom type="capsule" name="R_F_Paw_1_geom" size="0.05" fromto="0 0 0 -0.17953811585903168 0.16833937168121338 -0.06021338701248169"/>
                  <body name="R_F_Paw_2" pos="-0.17953811585903168 0.16833937168121338 -0.06021338701248169">
                  <joint type="hinge" name="rx_R_F_Paw_2" axis="1 0 0" range="-9.99999970909292 9.99999970909292"/>
                  <joint type="hinge" name="rz_R_F_Paw_2" axis="0 0 1" range="-45.00000125223908 45.00000125223908"/>
                  <geom type="capsule" name="R_F_Paw_2_geom" size="0.05" fromto="0 0 0 0.014132246375083923 -0.039042651653289795 -0.3441533148288727"/>
                    <body name="R_F_Paw_3" pos="0.014132246375083923 -0.039042651653289795 -0.3441533148288727">
                    <geom type="capsule" name="R_F_Paw_3_geom" size="0.05" fromto="0 0 0 0.02181607484817505 -0.09817063808441162 -0.17515107989311218"/>
                      <body name="R_F_Finger_2_1" pos="0.02181607484817505 -0.09817063808441162 -0.17515107989311218">
                      <geom type="capsule" name="R_F_Finger_2_1_geom" size="0.05" fromto="0 0 0 0.0023449212312698364 -0.0585518479347229 -0.010070694610476494"/>
                        <body name="R_F_Finger_2_2" pos="0.0023449212312698364 -0.0585518479347229 -0.010070694610476494">
                        <geom type="capsule" name="R_F_Finger_2_2_geom" size="0.05" fromto="0 0 0 0.003160819411277771 -0.054094672203063965 -0.013577761128544807"/>
                          <body name="R_F_Finger_2_3" pos="0.003160819411277771 -0.054094672203063965 -0.013577761128544807">
                          <geom type="capsule" name="R_F_Finger_2_3_geom" size="0.05" fromto="0 0 0 0.0014780610799789429 -0.03571367263793945 -0.015574171207845211"/>
                          </body>
                        </body>
                      </body>
                      <body name="R_F_Finger_3_1" pos="0.02181607484817505 -0.09817063808441162 -0.17515107989311218">
                      <geom type="capsule" name="R_F_Finger_3_1_geom" size="0.05" fromto="0 0 0 -0.028311967849731445 -0.05318993330001831 -0.00656876340508461"/>
                        <body name="R_F_Finger_3_2" pos="-0.028311967849731445 -0.05318993330001831 -0.00656876340508461">
                        <geom type="capsule" name="R_F_Finger_3_2_geom" size="0.05" fromto="0 0 0 -0.01821209490299225 -0.04630100727081299 -0.007779574021697044"/>
                          <body name="R_F_Finger_3_3" pos="-0.01821209490299225 -0.04630100727081299 -0.007779574021697044">
                          <geom type="capsule" name="R_F_Finger_3_3_geom" size="0.05" fromto="0 0 0 -0.013797998428344727 -0.03786909580230713 -0.011330235749483109"/>
                          </body>
                        </body>
                      </body>
                      <body name="R_F_Finger_4_1" pos="0.02181607484817505 -0.09817063808441162 -0.17515107989311218">
                      <geom type="capsule" name="R_F_Finger_4_1_geom" size="0.05" fromto="0 0 0 -0.046337783336639404 -0.029399394989013672 -0.02722940407693386"/>
                        <body name="R_F_Finger_4_2" pos="-0.046337783336639404 -0.029399394989013672 -0.02722940407693386">
                        <geom type="capsule" name="R_F_Finger_4_2_geom" size="0.05" fromto="0 0 0 -0.025139272212982178 -0.022921442985534668 -0.003358124755322933"/>
                          <body name="R_F_Finger_4_3" pos="-0.025139272212982178 -0.022921442985534668 -0.003358124755322933">
                          <geom type="capsule" name="R_F_Finger_4_3_geom" size="0.05" fromto="0 0 0 -0.02037981152534485 -0.01885223388671875 -0.01092312391847372"/>
                          </body>
                        </body>
                      </body>
                      <body name="R_F_Finger_1_1" pos="0.02181607484817505 -0.09817063808441162 -0.17515107989311218">
                      <geom type="capsule" name="R_F_Finger_1_1_geom" size="0.05" fromto="0 0 0 0.031319648027420044 -0.041713058948516846 -0.024164261296391487"/>
                        <body name="R_F_Finger_1_2" pos="0.031319648027420044 -0.041713058948516846 -0.024164261296391487">
                        <geom type="capsule" name="R_F_Finger_1_2_geom" size="0.05" fromto="0 0 0 0.026167765259742737 -0.03220933675765991 3.2845884561538696e-05"/>
                          <body name="R_F_Finger_1_3" pos="0.026167765259742737 -0.03220933675765991 3.2845884561538696e-05">
                          <geom type="capsule" name="R_F_Finger_1_3_geom" size="0.05" fromto="0 0 0 0.019394315779209137 -0.02483123540878296 -0.0109729478135705"/>
                          </body>
                        </body>
                      </body>
                    </body>
                  </body>
                </body>
              </body>
              <body name="R_Rib_5" pos="0.0 -0.2308562994003296 -0.08291542530059814">
              <geom type="capsule" name="R_Rib_5_geom" size="0.05" fromto="0 0 0 -0.1704041063785553 0.08789777755737305 -0.23081496357917786"/>
              </body>
              <body name="L_Rib_5" pos="0.0 -0.2308562994003296 -0.08291542530059814">
              <geom type="capsule" name="L_Rib_5_geom" size="0.05" fromto="0 0 0 0.170278400182724 0.08789783716201782 -0.2308150827884674"/>
              </body>
            </body>
            <body name="R_Rib_4" pos="0.0 -0.2558934688568115 -0.008959829807281494">
            <geom type="capsule" name="R_Rib_4_geom" size="0.05" fromto="0 0 0 -0.15984874963760376 0.048999011516571045 -0.2935454249382019"/>
            </body>
            <body name="L_Rib_4" pos="0.0 -0.2558934688568115 -0.008959829807281494">
            <geom type="capsule" name="L_Rib_4_geom" size="0.05" fromto="0 0 0 0.15972281992435455 0.04899895191192627 -0.2935451865196228"/>
            </body>
          </body>
          <body name="R_Rib_3" pos="0.0 -0.2097725123167038 0.021728336811065674">
          <geom type="capsule" name="R_Rib_3_geom" size="0.05" fromto="0 0 0 -0.15795756876468658 0.009853675961494446 -0.2894597351551056"/>
          </body>
          <body name="L_Rib_3" pos="0.0 -0.2097725123167038 0.021728336811065674">
          <geom type="capsule" name="L_Rib_3_geom" size="0.05" fromto="0 0 0 0.15783175826072693 0.009853675961494446 -0.28945961594581604"/>
          </body>
        </body>
      </body>
      <body name="Tail_1" pos="0.0 -0.07109183073043823 -0.09252709150314331">
      <joint type="hinge" name="rx_Tail_1" axis="1 0 0" range="-4.99999985454646 4.99999985454646"/>
      <joint type="hinge" name="rz_Tail_1" axis="0 0 1" range="-4.99999985454646 4.99999985454646"/>
      <geom type="capsule" name="Tail_1_geom" size="0.05" fromto="0 0 0 0.0 0.19382226467132568 -0.14527785778045654"/>
        <body name="Tail_2" pos="0.0 0.19382226467132568 -0.14527785778045654">
        <joint type="hinge" name="rx_Tail_2" axis="1 0 0" range="-4.99999985454646 4.99999985454646"/>
        <joint type="hinge" name="rz_Tail_2" axis="0 0 1" range="-4.99999985454646 4.99999985454646"/>
        <geom type="capsule" name="Tail_2_geom" size="0.05" fromto="0 0 0 0.0 0.11086165904998779 -0.08177107572555542"/>
          <body name="Tail_3" pos="0.0 0.11086165904998779 -0.08177107572555542">
          <joint type="hinge" name="rx_Tail_3" axis="1 0 0" range="-4.99999985454646 4.99999985454646"/>
          <joint type="hinge" name="rz_Tail_3" axis="0 0 1" range="-4.99999985454646 4.99999985454646"/>
          <geom type="capsule" name="Tail_3_geom" size="0.05" fromto="0 0 0 0.0 0.11859244108200073 -0.052198827266693115"/>
            <body name="Tail_4" pos="0.0 0.11859244108200073 -0.052198827266693115">
            <joint type="hinge" name="rx_Tail_4" axis="1 0 0" range="-4.99999985454646 4.99999985454646"/>
            <joint type="hinge" name="rz_Tail_4" axis="0 0 1" range="-4.99999985454646 4.99999985454646"/>
            <geom type="capsule" name="Tail_4_geom" size="0.05" fromto="0 0 0 0.0 0.12198221683502197 -0.054768264293670654"/>
              <body name="Tail_5" pos="0.0 0.12198221683502197 -0.054768264293670654">
              <joint type="hinge" name="rx_Tail_5" axis="1 0 0" range="-4.99999985454646 4.99999985454646"/>
              <joint type="hinge" name="rz_Tail_5" axis="0 0 1" range="-4.99999985454646 4.99999985454646"/>
              <geom type="capsule" name="Tail_5_geom" size="0.05" fromto="0 0 0 0.0 0.11853504180908203 -0.03858238458633423"/>
                <body name="Tail_6" pos="0.0 0.11853504180908203 -0.03858238458633423">
                <joint type="hinge" name="rx_Tail_6" axis="1 0 0" range="-4.99999985454646 4.99999985454646"/>
                <joint type="hinge" name="rz_Tail_6" axis="0 0 1" range="-4.99999985454646 4.99999985454646"/>
                <geom type="capsule" name="Tail_6_geom" size="0.05" fromto="0 0 0 0.0 0.12328189611434937 -0.02907276153564453"/>
                  <body name="Tail_7" pos="0.0 0.12328189611434937 -0.02907276153564453">
                  <joint type="hinge" name="rx_Tail_7" axis="1 0 0" range="-4.99999985454646 4.99999985454646"/>
                  <joint type="hinge" name="rz_Tail_7" axis="0 0 1" range="-4.99999985454646 4.99999985454646"/>
                  <geom type="capsule" name="Tail_7_geom" size="0.05" fromto="0 0 0 0.0 0.12698960304260254 -0.021487578749656677"/>
                    <body name="Tail_8" pos="0.0 0.12698960304260254 -0.021487578749656677">
                    <joint type="hinge" name="rx_Tail_8" axis="1 0 0" range="-4.99999985454646 4.99999985454646"/>
                    <joint type="hinge" name="rz_Tail_8" axis="0 0 1" range="-4.99999985454646 4.99999985454646"/>
                    <geom type="capsule" name="Tail_8_geom" size="0.05" fromto="0 0 0 0.0 0.12981581687927246 -0.01584780216217041"/>
                      <body name="Tail_9" pos="0.0 0.12981581687927246 -0.01584780216217041">
                      <joint type="hinge" name="rx_Tail_9" axis="1 0 0" range="-4.99999985454646 4.99999985454646"/>
                      <joint type="hinge" name="rz_Tail_9" axis="0 0 1" range="-4.99999985454646 4.99999985454646"/>
                      <geom type="capsule" name="Tail_9_geom" size="0.05" fromto="0 0 0 0.0 0.1312851905822754 -0.013129889965057373"/>
                        <body name="Tail_10" pos="0.0 0.1312851905822754 -0.013129889965057373">
                        <joint type="hinge" name="rx_Tail_10" axis="1 0 0" range="-4.99999985454646 4.99999985454646"/>
                        <joint type="hinge" name="rz_Tail_10" axis="0 0 1" range="-4.99999985454646 4.99999985454646"/>
                        <geom type="capsule" name="Tail_10_geom" size="0.05" fromto="0 0 0 0.0 0.13169467449188232 -0.011130914092063904"/>
                          <body name="Tail_11" pos="0.0 0.13169467449188232 -0.011130914092063904">
                          <joint type="hinge" name="rx_Tail_11" axis="1 0 0" range="-4.99999985454646 4.99999985454646"/>
                          <joint type="hinge" name="rz_Tail_11" axis="0 0 1" range="-4.99999985454646 4.99999985454646"/>
                          <geom type="capsule" name="Tail_11_geom" size="0.05" fromto="0 0 0 0.0 0.13223564624786377 -0.009466737508773804"/>
                            <body name="Tail_12" pos="0.0 0.13223564624786377 -0.009466737508773804">
                            <joint type="hinge" name="rx_Tail_12" axis="1 0 0" range="-4.99999985454646 4.99999985454646"/>
                            <joint type="hinge" name="rz_Tail_12" axis="0 0 1" range="-4.99999985454646 4.99999985454646"/>
                            <geom type="capsule" name="Tail_12_geom" size="0.05" fromto="0 0 0 0.0029128193855285645 0.1335829496383667 -0.008842617273330688"/>
                            </body>
                          </body>
                        </body>
                      </body>
                    </body>
                  </body>
                </body>
              </body>
            </body>
          </body>
        </body>
      </body>
      <body name="R_B_Paw_1" pos="0.0 -0.07109183073043823 -0.09252709150314331">
      <joint type="hinge" name="rx_R_B_Paw_1" axis="1 0 0" range="-39.99999883637168 39.99999883637168"/>
      <joint type="hinge" name="ry_R_B_Paw_1" axis="0 1 0" range="-9.99999970909292 19.99999941818584"/>
      <joint type="hinge" name="rz_R_B_Paw_1" axis="0 0 1" range="-9.99999970909292 19.99999941818584"/>
      <geom type="capsule" name="R_B_Paw_1_geom" size="0.05" fromto="0 0 0 -0.12856116890907288 -0.06068773567676544 -0.1629948616027832"/>
        <body name="R_B_Paw_2" pos="-0.12856116890907288 -0.06068773567676544 -0.1629948616027832">
        <joint type="hinge" name="rx_R_B_Paw_2" axis="1 0 0" range="-45.00000125223908 50.0000002530119"/>
        <joint type="hinge" name="rz_R_B_Paw_2" axis="0 0 1" range="-25.999999585151052 19.99999941818584"/>
        <geom type="capsule" name="R_B_Paw_2_geom" size="0.05" fromto="0 0 0 -0.1057131290435791 -0.26967060565948486 -0.16305962204933167"/>
          <body name="R_B_Paw_3" pos="-0.1057131290435791 -0.26967060565948486 -0.16305962204933167">
          <geom type="capsule" name="R_B_Paw_3_geom" size="0.05" fromto="0 0 0 0.007300645112991333 0.27059853076934814 -0.14332710206508636"/>
            <body name="R_B_Paw_4" pos="0.007300645112991333 0.27059853076934814 -0.14332710206508636">
            <geom type="capsule" name="R_B_Paw_4_geom" size="0.05" fromto="0 0 0 0.006926417350769043 -0.07383957505226135 -0.13510023057460785"/>
              <body name="R_B_Finger_1_1" pos="0.006926417350769043 -0.07383957505226135 -0.13510023057460785">
              <geom type="capsule" name="R_B_Finger_1_1_geom" size="0.05" fromto="0 0 0 0.05062621831893921 -0.013811320066452026 -0.03395810350775719"/>
                <body name="R_B_Finger_1_2" pos="0.05062621831893921 -0.013811320066452026 -0.03395810350775719">
                <geom type="capsule" name="R_B_Finger_1_2_geom" size="0.05" fromto="0 0 0 0.005271047353744507 -0.025599569082260132 -0.015743765980005264"/>
                  <body name="R_B_Finger_1_3" pos="0.005271047353744507 -0.025599569082260132 -0.015743765980005264">
                  <geom type="capsule" name="R_B_Finger_1_3_geom" size="0.05" fromto="0 0 0 0.0033015161752700806 -0.016032546758651733 -0.01157632376998663"/>
                  </body>
                </body>
              </body>
              <body name="R_B_Finger_2_1" pos="0.006926417350769043 -0.07383957505226135 -0.13510023057460785">
              <geom type="capsule" name="R_B_Finger_2_1_geom" size="0.05" fromto="0 0 0 0.023152485489845276 -0.0402398407459259 -0.023621879518032074"/>
                <body name="R_B_Finger_2_2" pos="0.023152485489845276 -0.0402398407459259 -0.023621879518032074">
                <geom type="capsule" name="R_B_Finger_2_2_geom" size="0.05" fromto="0 0 0 0.0022902637720108032 -0.06750750541687012 -8.126720786094666e-05"/>
                  <body name="R_B_Finger_2_3" pos="0.0022902637720108032 -0.06750750541687012 -8.126720786094666e-05">
                  <geom type="capsule" name="R_B_Finger_2_3_geom" size="0.05" fromto="0 0 0 0.002057865262031555 -0.047204069793224335 -0.020307039842009544"/>
                  </body>
                </body>
              </body>
              <body name="R_B_Finger_3_1" pos="0.006926417350769043 -0.07383957505226135 -0.13510023057460785">
              <geom type="capsule" name="R_B_Finger_3_1_geom" size="0.05" fromto="0 0 0 -0.0052787065505981445 -0.03944149613380432 -0.012112434953451157"/>
                <body name="R_B_Finger_3_2" pos="-0.0052787065505981445 -0.03944149613380432 -0.012112434953451157">
                <geom type="capsule" name="R_B_Finger_3_2_geom" size="0.05" fromto="0 0 0 -0.01556369662284851 -0.07996445149183273 -0.018579041585326195"/>
                  <body name="R_B_Finger_3_3" pos="-0.01556369662284851 -0.07996445149183273 -0.018579041585326195">
                  <geom type="capsule" name="R_B_Finger_3_3_geom" size="0.05" fromto="0 0 0 -0.007601529359817505 -0.043535735458135605 -0.01881965436041355"/>
                  </body>
                </body>
              </body>
              <body name="R_B_Finger_4_1" pos="0.006926417350769043 -0.07383957505226135 -0.13510023057460785">
              <geom type="capsule" name="R_B_Finger_4_1_geom" size="0.05" fromto="0 0 0 -0.029244542121887207 -0.02724441885948181 -0.019830886274576187"/>
                <body name="R_B_Finger_4_2" pos="-0.029244542121887207 -0.02724441885948181 -0.019830886274576187">
                <geom type="capsule" name="R_B_Finger_4_2_geom" size="0.05" fromto="0 0 0 -0.034585773944854736 -0.06896094232797623 -0.001878984272480011"/>
                  <body name="R_B_Finger_4_3" pos="-0.034585773944854736 -0.06896094232797623 -0.001878984272480011">
                  <geom type="capsule" name="R_B_Finger_4_3_geom" size="0.05" fromto="0 0 0 -0.02458667755126953 -0.04846162721514702 -0.01775800995528698"/>
                  </body>
                </body>
              </body>
              <body name="R_B_Finger_5_1" pos="0.006926417350769043 -0.07383957505226135 -0.13510023057460785">
              <geom type="capsule" name="R_B_Finger_5_1_geom" size="0.05" fromto="0 0 0 -0.04613658785820007 0.01041865348815918 -0.03638231009244919"/>
                <body name="R_B_Finger_5_2" pos="-0.04613658785820007 0.01041865348815918 -0.03638231009244919">
                <geom type="capsule" name="R_B_Finger_5_2_geom" size="0.05" fromto="0 0 0 -0.03107309341430664 -0.03808602690696716 -0.005154401063919067"/>
                  <body name="R_B_Finger_5_3" pos="-0.03107309341430664 -0.03808602690696716 -0.005154401063919067">
                  <geom type="capsule" name="R_B_Finger_5_3_geom" size="0.05" fromto="0 0 0 -0.023181915283203125 -0.02791590243577957 -0.0078057218343019485"/>
                  </body>
                </body>
              </body>
            </body>
          </body>
        </body>
      </body>
      <body name="L_B_Paw_1" pos="0.0 -0.07109183073043823 -0.09252709150314331">
      <joint type="hinge" name="rx_L_B_Paw_1" axis="1 0 0" range="-39.99999883637168 39.99999883637168"/>
      <joint type="hinge" name="ry_L_B_Paw_1" axis="0 1 0" range="-9.99999970909292 19.99999941818584"/>
      <joint type="hinge" name="rz_L_B_Paw_1" axis="0 0 1" range="-19.99999941818584 9.99999970909292"/>
      <geom type="capsule" name="L_B_Paw_1_geom" size="0.05" fromto="0 0 0 0.12856115400791168 -0.06068772077560425 -0.1629948616027832"/>
        <body name="L_B_Paw_2" pos="0.12856115400791168 -0.06068772077560425 -0.1629948616027832">
        <joint type="hinge" name="rx_L_B_Paw_2" axis="1 0 0" range="-45.00000125223908 50.0000002530119"/>
        <joint type="hinge" name="rz_L_B_Paw_2" axis="0 0 1" range="-19.99999941818584 25.999999585151052"/>
        <geom type="capsule" name="L_B_Paw_2_geom" size="0.05" fromto="0 0 0 0.10558734834194183 -0.26967060565948486 -0.16305959224700928"/>
          <body name="L_B_Paw_3" pos="0.10558734834194183 -0.26967060565948486 -0.16305959224700928">
          <geom type="capsule" name="L_B_Paw_3_geom" size="0.05" fromto="0 0 0 -0.007300674915313721 0.27059853076934814 -0.14332720637321472"/>
            <body name="L_B_Paw_4" pos="-0.007300674915313721 0.27059853076934814 -0.14332720637321472">
            <geom type="capsule" name="L_B_Paw_4_geom" size="0.05" fromto="0 0 0 -0.006800621747970581 -0.07383954524993896 -0.13510014116764069"/>
              <body name="L_B_Finger_1_1" pos="-0.006800621747970581 -0.07383954524993896 -0.13510014116764069">
              <geom type="capsule" name="L_B_Finger_1_1_geom" size="0.05" fromto="0 0 0 -0.05062621831893921 -0.013811305165290833 -0.0339580774307251"/>
                <body name="L_B_Finger_1_2" pos="-0.05062621831893921 -0.013811305165290833 -0.0339580774307251">
                <geom type="capsule" name="L_B_Finger_1_2_geom" size="0.05" fromto="0 0 0 -0.005271017551422119 -0.025599569082260132 -0.015743745490908623"/>
                  <body name="L_B_Finger_1_3" pos="-0.005271017551422119 -0.025599569082260132 -0.015743745490908623">
                  <geom type="capsule" name="L_B_Finger_1_3_geom" size="0.05" fromto="0 0 0 -0.0033015012741088867 -0.016032539308071136 -0.011576320044696331"/>
                  </body>
                </body>
              </body>
              <body name="L_B_Finger_2_1" pos="-0.006800621747970581 -0.07383954524993896 -0.13510014116764069">
              <geom type="capsule" name="L_B_Finger_2_1_geom" size="0.05" fromto="0 0 0 -0.023152485489845276 -0.04023982584476471 -0.023621857166290283"/>
                <body name="L_B_Finger_2_2" pos="-0.023152485489845276 -0.04023982584476471 -0.023621857166290283">
                <geom type="capsule" name="L_B_Finger_2_2_geom" size="0.05" fromto="0 0 0 -0.0022902637720108032 -0.06750747561454773 -8.125975728034973e-05"/>
                  <body name="L_B_Finger_2_3" pos="-0.0022902637720108032 -0.06750747561454773 -8.125975728034973e-05">
                  <geom type="capsule" name="L_B_Finger_2_3_geom" size="0.05" fromto="0 0 0 -0.0020578503608703613 -0.04720405489206314 -0.020307037979364395"/>
                  </body>
                </body>
              </body>
              <body name="L_B_Finger_3_1" pos="-0.006800621747970581 -0.07383954524993896 -0.13510014116764069">
              <geom type="capsule" name="L_B_Finger_3_1_geom" size="0.05" fromto="0 0 0 0.005278676748275757 -0.03944147378206253 -0.012112416326999664"/>
                <body name="L_B_Finger_3_2" pos="0.005278676748275757 -0.03944147378206253 -0.012112416326999664">
                <geom type="capsule" name="L_B_Finger_3_2_geom" size="0.05" fromto="0 0 0 0.015563726425170898 -0.07996441423892975 -0.0185790304094553"/>
                  <body name="L_B_Finger_3_3" pos="0.015563726425170898 -0.07996441423892975 -0.0185790304094553">
                  <geom type="capsule" name="L_B_Finger_3_3_geom" size="0.05" fromto="0 0 0 0.007601499557495117 -0.04353567585349083 -0.01881963014602661"/>
                  </body>
                </body>
              </body>
              <body name="L_B_Finger_4_1" pos="-0.006800621747970581 -0.07383954524993896 -0.13510014116764069">
              <geom type="capsule" name="L_B_Finger_4_1_geom" size="0.05" fromto="0 0 0 0.02924451231956482 -0.027244411408901215 -0.019830867648124695"/>
                <body name="L_B_Finger_4_2" pos="0.02924451231956482 -0.027244411408901215 -0.019830867648124695">
                <geom type="capsule" name="L_B_Finger_4_2_geom" size="0.05" fromto="0 0 0 0.03458575904369354 -0.06896091252565384 -0.0018789581954479218"/>
                  <body name="L_B_Finger_4_3" pos="0.03458575904369354 -0.06896091252565384 -0.0018789581954479218">
                  <geom type="capsule" name="L_B_Finger_4_3_geom" size="0.05" fromto="0 0 0 0.024586662650108337 -0.04846159368753433 -0.017758004367351532"/>
                  </body>
                </body>
              </body>
              <body name="L_B_Finger_5_1" pos="-0.006800621747970581 -0.07383954524993896 -0.13510014116764069">
              <geom type="capsule" name="L_B_Finger_5_1_geom" size="0.05" fromto="0 0 0 0.046136513352394104 0.01041865348815918 -0.0363822877407074"/>
                <body name="L_B_Finger_5_2" pos="0.046136513352394104 0.01041865348815918 -0.0363822877407074">
                <geom type="capsule" name="L_B_Finger_5_2_geom" size="0.05" fromto="0 0 0 0.03107304871082306 -0.03808604180812836 -0.005154384300112724"/>
                  <body name="L_B_Finger_5_3" pos="0.03107304871082306 -0.03808604180812836 -0.005154384300112724">
                  <geom type="capsule" name="L_B_Finger_5_3_geom" size="0.05" fromto="0 0 0 0.0231819748878479 -0.027915894985198975 -0.00780571810901165"/>
                  </body>
                </body>
              </body>
            </body>
          </body>
        </body>
      </body>
    </body>
  </worldbody>
<asset>
<texture name="grid" type="2d" builtin="checker" width="512" height="512" rgb1=".1 .2 .3" rgb2=".2 .3 .4"/>
<material name="grid" texture="grid" texrepeat="1 1" texuniform="true" reflectance=".2"/>
  </asset></mujoco>
