<mujoco>
  <compiler meshdir="./mesh"/>
  <worldbody>
      <geom name="floor" size="0 0 .05" type="plane" material="grid" condim="3"/>
    <body name="Back_1" pos="-0.03638419508934021 0.32031768560409546 0.75876384973526">
    <joint type="free"/>
    <geom type="capsule" name="Back_1_geom" size="0.05" fromto="0 0 0 0.0 -0.07109183073043823 -0.09252709150314331"/>
      <body name="Back_2" pos="0.0 -0.07109183073043823 -0.09252709150314331">
      <joint type="hinge" name="rx_Back_2" axis="1 0 0" range="-9.99999970909292 9.99999970909292"/>
      <joint type="hinge" name="ry_Back_2" axis="0 1 0" range="-4.99999985454646 4.99999985454646"/>
      <joint type="hinge" name="rz_Back_2" axis="0 0 1" range="-9.99999970909292 6.000000166965211"/>
      <geom type="capsule" name="Back_2_geom" size="0.05" fromto="0 0 0 0.0 -0.2740018367767334 0.09516853094100952"/>
        <body name="Back_3" pos="0.0 -0.2740018367767334 0.09516853094100952">
        <joint type="hinge" name="rx_Back_3" axis="1 0 0" range="-9.99999970909292 9.99999970909292"/>
        <joint type="hinge" name="ry_Back_3" axis="0 1 0" range="-4.99999985454646 4.99999985454646"/>
        <joint type="hinge" name="rz_Back_3" axis="0 0 1" range="-9.99999970909292 6.000000166965211"/>
        <geom type="capsule" name="Back_3_geom" size="0.05" fromto="0 0 0 0.0 -0.2097725123167038 0.021728336811065674"/>
          <body name="Back_4" pos="0.0 -0.2097725123167038 0.021728336811065674">
          <joint type="hinge" name="rx_Back_4" axis="1 0 0" range="-9.99999970909292 9.99999970909292"/>
          <joint type="hinge" name="ry_Back_4" axis="0 1 0" range="-4.99999985454646 4.99999985454646"/>
          <joint type="hinge" name="rz_Back_4" axis="0 0 1" range="-9.99999970909292 6.000000166965211"/>
          <geom type="capsule" name="Back_4_geom" size="0.05" fromto="0 0 0 0.0 -0.2558934688568115 -0.008959829807281494"/>
            <body name="Back_5" pos="0.0 -0.2558934688568115 -0.008959829807281494">
            <joint type="hinge" name="rx_Back_5" axis="1 0 0" range="-9.99999970909292 9.99999970909292"/>
            <joint type="hinge" name="ry_Back_5" axis="0 1 0" range="-4.99999985454646 4.99999985454646"/>
            <joint type="hinge" name="rz_Back_5" axis="0 0 1" range="-9.99999970909292 6.000000166965211"/>
            <geom type="capsule" name="Back_5_geom" size="0.05" fromto="0 0 0 0.0 -0.2308562994003296 -0.08291542530059814"/>
              <body name="Back_6" pos="0.0 -0.2308562994003296 -0.08291542530059814">
              <joint type="hinge" name="rx_Back_6" axis="1 0 0" range="-9.99999970909292 9.99999970909292"/>
              <joint type="hinge" name="ry_Back_6" axis="0 1 0" range="-4.99999985454646 4.99999985454646"/>
              <joint type="hinge" name="rz_Back_6" axis="0 0 1" range="-9.99999970909292 6.000000166965211"/>
              <geom type="capsule" name="Back_6_geom" size="0.05" fromto="0 0 0 0.0 -0.2347009778022766 -0.07146763801574707"/>
                <body name="Neck" pos="0.0 -0.2347009778022766 -0.07146763801574707">
                <geom type="capsule" name="Neck_geom" size="0.05" fromto="0 0 0 0.0 -0.18661510944366455 0.0330730676651001"/>
                  <body name="Head" pos="0.0 -0.18661510944366455 0.0330730676651001">
                  <geom type="capsule" name="Head_geom" size="0.05" fromto="0 0 0 -0.003004610538482666 -0.18622291088104248 -0.011018574237823486"/>
                    <body name="L_Ear_1" pos="-0.003004610538482666 -0.18622291088104248 -0.011018574237823486">
                    <geom type="capsule" name="L_Ear_1_geom" size="0.05" fromto="0 0 0 0.0987759679555893 0.10522949695587158 0.02556777000427246"/>
                      <body name="L_Ear_2" pos="0.0987759679555893 0.10522949695587158 0.02556777000427246">
                      <geom type="capsule" name="L_Ear_2_geom" size="0.05" fromto="0 0 0 0.1209293007850647 0.06745648384094238 0.010155320167541504"/>
                        <body name="L_Ear_3" pos="0.1209293007850647 0.06745648384094238 0.010155320167541504">
                        <geom type="capsule" name="L_Ear_3_geom" size="0.05" fromto="0 0 0 0.0458882600069046 0.02377474308013916 0.02690833806991577"/>
                        </body>
                      </body>
                    </body>
                    <body name="Jaw_1" pos="-0.003004610538482666 -0.18622291088104248 -0.011018574237823486">
                    <geom type="capsule" name="Jaw_1_geom" size="0.05" fromto="0 0 0 0.003004610538482666 -0.12477743625640869 -0.2739276885986328"/>
                      <body name="Jaw_2" pos="0.003004610538482666 -0.12477743625640869 -0.2739276885986328">
                      <geom type="capsule" name="Jaw_2_geom" size="0.05" fromto="0 0 0 0.002912815660238266 -0.13363265991210938 -0.018688827753067017"/>
                      </body>
                    </body>
                    <body name="R_Ear_1" pos="-0.003004610538482666 -0.18622291088104248 -0.011018574237823486">
                    <geom type="capsule" name="R_Ear_1_geom" size="0.05" fromto="0 0 0 -0.09276671707630157 0.10522949695587158 0.02556777000427246"/>
                      <body name="R_Ear_2" pos="-0.09276671707630157 0.10522949695587158 0.02556777000427246">
                      <geom type="capsule" name="R_Ear_2_geom" size="0.05" fromto="0 0 0 -0.12092931568622589 0.06745648384094238 0.010155320167541504"/>
                        <body name="R_Ear_3" pos="-0.12092931568622589 0.06745648384094238 0.010155320167541504">
                        <geom type="capsule" name="R_Ear_3_geom" size="0.05" fromto="0 0 0 -0.04588821530342102 0.02377474308013916 0.02690833806991577"/>
                        </body>
                      </body>
                    </body>
                    <body name="Nose" pos="-0.003004610538482666 -0.18622291088104248 -0.011018574237823486">
                    <geom type="capsule" name="Nose_geom" size="0.05" fromto="0 0 0 7.450580596923828e-09 -0.3301737308502197 -0.12187623977661133"/>
                    </body>
                  </body>
                </body>
                <body name="L_F_Paw_1" pos="0.0 -0.2347009778022766 -0.07146763801574707">
                <joint type="hinge" name="rx_L_F_Paw_1" axis="1 0 0" range="-30.000000834826057 30.000000834826057"/>
                <joint type="hinge" name="ry_L_F_Paw_1" axis="0 1 0" range="-19.99999941818584 19.99999941818584"/>
                <joint type="hinge" name="rz_L_F_Paw_1" axis="0 0 1" range="-30.000000834826057 30.000000834826057"/>
                <geom type="capsule" name="L_F_Paw_1_geom" size="0.05" fromto="0 0 0 0.17953817546367645 0.16833937168121338 -0.06021338701248169"/>
                  <body name="L_F_Paw_2" pos="0.17953817546367645 0.16833937168121338 -0.06021338701248169">
                  <joint type="hinge" name="rx_L_F_Paw_2" axis="1 0 0" range="-9.99999970909292 9.99999970909292"/>
                  <joint type="hinge" name="rz_L_F_Paw_2" axis="0 0 1" range="-45.00000125223908 45.00000125223908"/>
                  <geom type="capsule" name="L_F_Paw_2_geom" size="0.05" fromto="0 0 0 -0.014132246375083923 -0.039042651653289795 -0.34415319561958313"/>
                    <body name="L_F_Paw_3" pos="-0.014132246375083923 -0.039042651653289795 -0.34415319561958313">
                    <joint type="hinge" name="rz_L_F_Paw_3" axis="0 0 1" range="-30.000000834826057 30.000000834826057"/>
                    <geom type="capsule" name="L_F_Paw_3_geom" size="0.05" fromto="0 0 0 -0.021816067397594452 -0.09817075729370117 -0.17515115439891815"/>
                      <body name="L_F_Finger_2_1" pos="-0.021816067397594452 -0.09817075729370117 -0.17515115439891815">
                      <geom type="capsule" name="L_F_Finger_2_1_geom" size="0.05" fromto="0 0 0 -0.0023449361324310303 -0.0585518479347229 -0.010070698335766792"/>
                        <body name="L_F_Finger_2_2" pos="-0.0023449361324310303 -0.0585518479347229 -0.010070698335766792">
                        <geom type="capsule" name="L_F_Finger_2_2_geom" size="0.05" fromto="0 0 0 -0.003160804510116577 -0.054094672203063965 -0.013577762991189957"/>
                          <body name="L_F_Finger_2_3" pos="-0.003160804510116577 -0.054094672203063965 -0.013577762991189957">
                          <geom type="capsule" name="L_F_Finger_2_3_geom" size="0.05" fromto="0 0 0 -0.0014780759811401367 -0.03571367263793945 -0.015574176795780659"/>
                          </body>
                        </body>
                      </body>
                      <body name="L_F_Finger_3_1" pos="-0.021816067397594452 -0.09817075729370117 -0.17515115439891815">
                      <geom type="capsule" name="L_F_Finger_3_1_geom" size="0.05" fromto="0 0 0 0.028311945497989655 -0.05318993330001831 -0.0065687671303749084"/>
                        <body name="L_F_Finger_3_2" pos="0.028311945497989655 -0.05318993330001831 -0.0065687671303749084">
                        <geom type="capsule" name="L_F_Finger_3_2_geom" size="0.05" fromto="0 0 0 0.01821213960647583 -0.04630100727081299 -0.007779579609632492"/>
                          <body name="L_F_Finger_3_3" pos="0.01821213960647583 -0.04630100727081299 -0.007779579609632492">
                          <geom type="capsule" name="L_F_Finger_3_3_geom" size="0.05" fromto="0 0 0 0.013797998428344727 -0.03786909580230713 -0.011330236680805683"/>
                          </body>
                        </body>
                      </body>
                      <body name="L_F_Finger_4_1" pos="-0.021816067397594452 -0.09817075729370117 -0.17515115439891815">
                      <geom type="capsule" name="L_F_Finger_4_1_geom" size="0.05" fromto="0 0 0 0.046337805688381195 -0.029399394989013672 -0.027229413390159607"/>
                        <body name="L_F_Finger_4_2" pos="0.046337805688381195 -0.029399394989013672 -0.027229413390159607">
                        <geom type="capsule" name="L_F_Finger_4_2_geom" size="0.05" fromto="0 0 0 0.025139302015304565 -0.022921442985534668 -0.003358127549290657"/>
                          <body name="L_F_Finger_4_3" pos="0.025139302015304565 -0.022921442985534668 -0.003358127549290657">
                          <geom type="capsule" name="L_F_Finger_4_3_geom" size="0.05" fromto="0 0 0 0.02037981152534485 -0.01885223388671875 -0.010923127643764019"/>
                          </body>
                        </body>
                      </body>
                      <body name="L_F_Finger_1_1" pos="-0.021816067397594452 -0.09817075729370117 -0.17515115439891815">
                      <geom type="capsule" name="L_F_Finger_1_1_geom" size="0.05" fromto="0 0 0 -0.031319648027420044 -0.041713058948516846 -0.024164263159036636"/>
                        <body name="L_F_Finger_1_2" pos="-0.031319648027420044 -0.041713058948516846 -0.024164263159036636">
                        <geom type="capsule" name="L_F_Finger_1_2_geom" size="0.05" fromto="0 0 0 -0.026167772710323334 -0.03220939636230469 3.284960985183716e-05"/>
                          <body name="L_F_Finger_1_3" pos="-0.026167772710323334 -0.03220939636230469 3.284960985183716e-05">
                          <geom type="capsule" name="L_F_Finger_1_3_geom" size="0.05" fromto="0 0 0 -0.01939433254301548 -0.024831295013427734 -0.01097294595092535"/>
                          </body>
                        </body>
                      </body>
                    </body>
                  </body>
                </body>
                <body name="R_F_Paw_1" pos="0.0 -0.2347009778022766 -0.07146763801574707">
                <joint type="hinge" name="rx_R_F_Paw_1" axis="1 0 0" range="-30.000000834826057 30.000000834826057"/>
                <joint type="hinge" name="ry_R_F_Paw_1" axis="0 1 0" range="-19.99999941818584 19.99999941818584"/>
                <joint type="hinge" name="rz_R_F_Paw_1" axis="0 0 1" range="-30.000000834826057 30.000000834826057"/>
                <geom type="capsule" name="R_F_Paw_1_geom" size="0.05" fromto="0 0 0 -0.17953811585903168 0.16833937168121338 -0.06021338701248169"/>
                  <body name="R_F_Paw_2" pos="-0.17953811585903168 0.16833937168121338 -0.06021338701248169">
                  <joint type="hinge" name="rx_R_F_Paw_2" axis="1 0 0" range="-9.99999970909292 9.99999970909292"/>
                  <joint type="hinge" name="rz_R_F_Paw_2" axis="0 0 1" range="-45.00000125223908 45.00000125223908"/>
                  <geom type="capsule" name="R_F_Paw_2_geom" size="0.05" fromto="0 0 0 0.014132246375083923 -0.039042651653289795 -0.3441533148288727"/>
                    <body name="R_F_Paw_3" pos="0.014132246375083923 -0.039042651653289795 -0.3441533148288727">
                    <joint type="hinge" name="rz_R_F_Paw_3" axis="0 0 1" range="-30.000000834826057 30.000000834826057"/>
                    <geom type="capsule" name="R_F_Paw_3_geom" size="0.05" fromto="0 0 0 0.02181607484817505 -0.09817063808441162 -0.17515107989311218"/>
                      <body name="R_F_Finger_2_1" pos="0.02181607484817505 -0.09817063808441162 -0.17515107989311218">
                      <geom type="capsule" name="R_F_Finger_2_1_geom" size="0.05" fromto="0 0 0 0.0023449212312698364 -0.0585518479347229 -0.01007070392370224"/>
                        <body name="R_F_Finger_2_2" pos="0.0023449212312698364 -0.0585518479347229 -0.01007070392370224">
                        <geom type="capsule" name="R_F_Finger_2_2_geom" size="0.05" fromto="0 0 0 0.003160819411277771 -0.054094672203063965 -0.013577766716480255"/>
                          <body name="R_F_Finger_2_3" pos="0.003160819411277771 -0.054094672203063965 -0.013577766716480255">
                          <geom type="capsule" name="R_F_Finger_2_3_geom" size="0.05" fromto="0 0 0 0.0014780610799789429 -0.03571367263793945 -0.015574180521070957"/>
                          </body>
                        </body>
                      </body>
                      <body name="R_F_Finger_3_1" pos="0.02181607484817505 -0.09817063808441162 -0.17515107989311218">
                      <geom type="capsule" name="R_F_Finger_3_1_geom" size="0.05" fromto="0 0 0 -0.028311967849731445 -0.05318993330001831 -0.006568770855665207"/>
                        <body name="R_F_Finger_3_2" pos="-0.028311967849731445 -0.05318993330001831 -0.006568770855665207">
                        <geom type="capsule" name="R_F_Finger_3_2_geom" size="0.05" fromto="0 0 0 -0.01821209490299225 -0.04630100727081299 -0.007779577746987343"/>
                          <body name="R_F_Finger_3_3" pos="-0.01821209490299225 -0.04630100727081299 -0.007779577746987343">
                          <geom type="capsule" name="R_F_Finger_3_3_geom" size="0.05" fromto="0 0 0 -0.01379801332950592 -0.03786909580230713 -0.011330240406095982"/>
                          </body>
                        </body>
                      </body>
                      <body name="R_F_Finger_4_1" pos="0.02181607484817505 -0.09817063808441162 -0.17515107989311218">
                      <geom type="capsule" name="R_F_Finger_4_1_geom" size="0.05" fromto="0 0 0 -0.046337783336639404 -0.029399394989013672 -0.027229413390159607"/>
                        <body name="R_F_Finger_4_2" pos="-0.046337783336639404 -0.029399394989013672 -0.027229413390159607">
                        <geom type="capsule" name="R_F_Finger_4_2_geom" size="0.05" fromto="0 0 0 -0.025139272212982178 -0.022921442985534668 -0.003358127549290657"/>
                          <body name="R_F_Finger_4_3" pos="-0.025139272212982178 -0.022921442985534668 -0.003358127549290657">
                          <geom type="capsule" name="R_F_Finger_4_3_geom" size="0.05" fromto="0 0 0 -0.02037981152534485 -0.01885223388671875 -0.010923132300376892"/>
                          </body>
                        </body>
                      </body>
                      <body name="R_F_Finger_1_1" pos="0.02181607484817505 -0.09817063808441162 -0.17515107989311218">
                      <geom type="capsule" name="R_F_Finger_1_1_geom" size="0.05" fromto="0 0 0 0.031319648027420044 -0.04171311855316162 -0.024164274334907532"/>
                        <body name="R_F_Finger_1_2" pos="0.031319648027420044 -0.04171311855316162 -0.024164274334907532">
                        <geom type="capsule" name="R_F_Finger_1_2_geom" size="0.05" fromto="0 0 0 0.02616778016090393 -0.03220939636230469 3.2842159271240234e-05"/>
                          <body name="R_F_Finger_1_3" pos="0.02616778016090393 -0.03220939636230469 3.2842159271240234e-05">
                          <geom type="capsule" name="R_F_Finger_1_3_geom" size="0.05" fromto="0 0 0 0.019394338130950928 -0.02483123540878296 -0.010972957126796246"/>
                          </body>
                        </body>
                      </body>
                    </body>
                  </body>
                </body>
              </body>
              <body name="R_Rib_5" pos="0.0 -0.2308562994003296 -0.08291542530059814">
              <geom type="capsule" name="R_Rib_5_geom" size="0.05" fromto="0 0 0 -0.1704041063785553 0.08789783716201782 -0.23081496357917786"/>
              </body>
              <body name="L_Rib_5" pos="0.0 -0.2308562994003296 -0.08291542530059814">
              <geom type="capsule" name="L_Rib_5_geom" size="0.05" fromto="0 0 0 0.170278400182724 0.0878978967666626 -0.2308151125907898"/>
              </body>
            </body>
            <body name="R_Rib_4" pos="0.0 -0.2558934688568115 -0.008959829807281494">
            <geom type="capsule" name="R_Rib_4_geom" size="0.05" fromto="0 0 0 -0.15984874963760376 0.048999011516571045 -0.2935454845428467"/>
            </body>
            <body name="L_Rib_4" pos="0.0 -0.2558934688568115 -0.008959829807281494">
            <geom type="capsule" name="L_Rib_4_geom" size="0.05" fromto="0 0 0 0.15972281992435455 0.04899898171424866 -0.2935452461242676"/>
            </body>
          </body>
          <body name="R_Rib_3" pos="0.0 -0.2097725123167038 0.021728336811065674">
          <geom type="capsule" name="R_Rib_3_geom" size="0.05" fromto="0 0 0 -0.15795756876468658 0.009853675961494446 -0.28945979475975037"/>
          </body>
          <body name="L_Rib_3" pos="0.0 -0.2097725123167038 0.021728336811065674">
          <geom type="capsule" name="L_Rib_3_geom" size="0.05" fromto="0 0 0 0.15783175826072693 0.009853675961494446 -0.2894596755504608"/>
          </body>
        </body>
      </body>
      <body name="Tail_1" pos="0.0 -0.07109183073043823 -0.09252709150314331">
      <joint type="hinge" name="rx_Tail_1" axis="1 0 0" range="-4.99999985454646 4.99999985454646"/>
      <joint type="hinge" name="rz_Tail_1" axis="0 0 1" range="-4.99999985454646 4.99999985454646"/>
      <geom type="capsule" name="Tail_1_geom" size="0.05" fromto="0 0 0 0.0 0.19382226467132568 -0.14527785778045654"/>
        <body name="Tail_2" pos="0.0 0.19382226467132568 -0.14527785778045654">
        <joint type="hinge" name="rx_Tail_2" axis="1 0 0" range="-4.99999985454646 4.99999985454646"/>
        <joint type="hinge" name="rz_Tail_2" axis="0 0 1" range="-4.99999985454646 4.99999985454646"/>
        <geom type="capsule" name="Tail_2_geom" size="0.05" fromto="0 0 0 0.0 0.11086165904998779 -0.08177107572555542"/>
          <body name="Tail_3" pos="0.0 0.11086165904998779 -0.08177107572555542">
          <joint type="hinge" name="rx_Tail_3" axis="1 0 0" range="-4.99999985454646 4.99999985454646"/>
          <joint type="hinge" name="rz_Tail_3" axis="0 0 1" range="-4.99999985454646 4.99999985454646"/>
          <geom type="capsule" name="Tail_3_geom" size="0.05" fromto="0 0 0 0.0 0.11859244108200073 -0.052198827266693115"/>
            <body name="Tail_4" pos="0.0 0.11859244108200073 -0.052198827266693115">
            <joint type="hinge" name="rx_Tail_4" axis="1 0 0" range="-4.99999985454646 4.99999985454646"/>
            <joint type="hinge" name="rz_Tail_4" axis="0 0 1" range="-4.99999985454646 4.99999985454646"/>
            <geom type="capsule" name="Tail_4_geom" size="0.05" fromto="0 0 0 0.0 0.12198221683502197 -0.054768264293670654"/>
              <body name="Tail_5" pos="0.0 0.12198221683502197 -0.054768264293670654">
              <joint type="hinge" name="rx_Tail_5" axis="1 0 0" range="-4.99999985454646 4.99999985454646"/>
              <joint type="hinge" name="rz_Tail_5" axis="0 0 1" range="-4.99999985454646 4.99999985454646"/>
              <geom type="capsule" name="Tail_5_geom" size="0.05" fromto="0 0 0 0.0 0.11853504180908203 -0.03858238458633423"/>
                <body name="Tail_6" pos="0.0 0.11853504180908203 -0.03858238458633423">
                <joint type="hinge" name="rx_Tail_6" axis="1 0 0" range="-4.99999985454646 4.99999985454646"/>
                <joint type="hinge" name="rz_Tail_6" axis="0 0 1" range="-4.99999985454646 4.99999985454646"/>
                <geom type="capsule" name="Tail_6_geom" size="0.05" fromto="0 0 0 0.0 0.12328189611434937 -0.02907276153564453"/>
                  <body name="Tail_7" pos="0.0 0.12328189611434937 -0.02907276153564453">
                  <joint type="hinge" name="rx_Tail_7" axis="1 0 0" range="-4.99999985454646 4.99999985454646"/>
                  <joint type="hinge" name="rz_Tail_7" axis="0 0 1" range="-4.99999985454646 4.99999985454646"/>
                  <geom type="capsule" name="Tail_7_geom" size="0.05" fromto="0 0 0 0.0 0.12698960304260254 -0.021487578749656677"/>
                    <body name="Tail_8" pos="0.0 0.12698960304260254 -0.021487578749656677">
                    <joint type="hinge" name="rx_Tail_8" axis="1 0 0" range="-4.99999985454646 4.99999985454646"/>
                    <joint type="hinge" name="rz_Tail_8" axis="0 0 1" range="-4.99999985454646 4.99999985454646"/>
                    <geom type="capsule" name="Tail_8_geom" size="0.05" fromto="0 0 0 0.0 0.12981581687927246 -0.01584780216217041"/>
                      <body name="Tail_9" pos="0.0 0.12981581687927246 -0.01584780216217041">
                      <joint type="hinge" name="rx_Tail_9" axis="1 0 0" range="-4.99999985454646 4.99999985454646"/>
                      <joint type="hinge" name="rz_Tail_9" axis="0 0 1" range="-4.99999985454646 4.99999985454646"/>
                      <geom type="capsule" name="Tail_9_geom" size="0.05" fromto="0 0 0 0.0 0.1312851905822754 -0.013129889965057373"/>
                        <body name="Tail_10" pos="0.0 0.1312851905822754 -0.013129889965057373">
                        <joint type="hinge" name="rx_Tail_10" axis="1 0 0" range="-4.99999985454646 4.99999985454646"/>
                        <joint type="hinge" name="rz_Tail_10" axis="0 0 1" range="-4.99999985454646 4.99999985454646"/>
                        <geom type="capsule" name="Tail_10_geom" size="0.05" fromto="0 0 0 0.0 0.13169467449188232 -0.011130914092063904"/>
                          <body name="Tail_11" pos="0.0 0.13169467449188232 -0.011130914092063904">
                          <joint type="hinge" name="rx_Tail_11" axis="1 0 0" range="-4.99999985454646 4.99999985454646"/>
                          <joint type="hinge" name="rz_Tail_11" axis="0 0 1" range="-4.99999985454646 4.99999985454646"/>
                          <geom type="capsule" name="Tail_11_geom" size="0.05" fromto="0 0 0 0.0 0.13223564624786377 -0.009466737508773804"/>
                            <body name="Tail_12" pos="0.0 0.13223564624786377 -0.009466737508773804">
                            <joint type="hinge" name="rx_Tail_12" axis="1 0 0" range="-4.99999985454646 4.99999985454646"/>
                            <joint type="hinge" name="rz_Tail_12" axis="0 0 1" range="-4.99999985454646 4.99999985454646"/>
                            <geom type="capsule" name="Tail_12_geom" size="0.05" fromto="0 0 0 0.0029128193855285645 0.1335829496383667 -0.008842617273330688"/>
                            </body>
                          </body>
                        </body>
                      </body>
                    </body>
                  </body>
                </body>
              </body>
            </body>
          </body>
        </body>
      </body>
      <body name="R_B_Paw_1" pos="0.0 -0.07109183073043823 -0.09252709150314331">
      <joint type="hinge" name="rx_R_B_Paw_1" axis="1 0 0" range="-39.99999883637168 39.99999883637168"/>
      <joint type="hinge" name="rz_R_B_Paw_1" axis="0 0 1" range="-9.99999970909292 19.99999941818584"/>
      <geom type="capsule" name="R_B_Paw_1_geom" size="0.05" fromto="0 0 0 -0.12856116890907288 -0.06068773567676544 -0.1629948616027832"/>
        <body name="R_B_Paw_2" pos="-0.12856116890907288 -0.06068773567676544 -0.1629948616027832">
        <joint type="hinge" name="rx_R_B_Paw_2" axis="1 0 0" range="-19.99999941818584 19.99999941818584"/>
        <joint type="hinge" name="rz_R_B_Paw_2" axis="0 0 1" range="-30.000000834826057 30.000000834826057"/>
        <geom type="capsule" name="R_B_Paw_2_geom" size="0.05" fromto="0 0 0 -0.1057131290435791 -0.26967060565948486 -0.16305962204933167"/>
          <body name="R_B_Paw_3" pos="-0.1057131290435791 -0.26967060565948486 -0.16305962204933167">
          <geom type="capsule" name="R_B_Paw_3_geom" size="0.05" fromto="0 0 0 0.007300645112991333 0.27059853076934814 -0.14332710206508636"/>
            <body name="R_B_Paw_4" pos="0.007300645112991333 0.27059853076934814 -0.14332710206508636">
            <joint type="hinge" name="rz_R_B_Paw_4" axis="0 0 1" range="-19.99999941818584 19.99999941818584"/>
            <geom type="capsule" name="R_B_Paw_4_geom" size="0.05" fromto="0 0 0 0.006926417350769043 -0.07383957505226135 -0.13510023057460785"/>
              <body name="R_B_Finger_1_1" pos="0.006926417350769043 -0.07383957505226135 -0.13510023057460785">
              <geom type="capsule" name="R_B_Finger_1_1_geom" size="0.05" fromto="0 0 0 0.05062621831893921 -0.013811320066452026 -0.03395809978246689"/>
                <body name="R_B_Finger_1_2" pos="0.05062621831893921 -0.013811320066452026 -0.03395809978246689">
                <geom type="capsule" name="R_B_Finger_1_2_geom" size="0.05" fromto="0 0 0 0.005271047353744507 -0.025599569082260132 -0.015743762254714966"/>
                  <body name="R_B_Finger_1_3" pos="0.005271047353744507 -0.025599569082260132 -0.015743762254714966">
                  <geom type="capsule" name="R_B_Finger_1_3_geom" size="0.05" fromto="0 0 0 0.0033015161752700806 -0.016032546758651733 -0.011576322838664055"/>
                  </body>
                </body>
              </body>
              <body name="R_B_Finger_2_1" pos="0.006926417350769043 -0.07383957505226135 -0.13510023057460785">
              <geom type="capsule" name="R_B_Finger_2_1_geom" size="0.05" fromto="0 0 0 0.023152485489845276 -0.0402398407459259 -0.023621879518032074"/>
                <body name="R_B_Finger_2_2" pos="0.023152485489845276 -0.0402398407459259 -0.023621879518032074">
                <geom type="capsule" name="R_B_Finger_2_2_geom" size="0.05" fromto="0 0 0 0.0022902637720108032 -0.06750748306512833 -8.12634825706482e-05"/>
                  <body name="R_B_Finger_2_3" pos="0.0022902637720108032 -0.06750748306512833 -8.12634825706482e-05">
                  <geom type="capsule" name="R_B_Finger_2_3_geom" size="0.05" fromto="0 0 0 0.002057865262031555 -0.047204043716192245 -0.020307043567299843"/>
                  </body>
                </body>
              </body>
              <body name="R_B_Finger_3_1" pos="0.006926417350769043 -0.07383957505226135 -0.13510023057460785">
              <geom type="capsule" name="R_B_Finger_3_1_geom" size="0.05" fromto="0 0 0 -0.0052787065505981445 -0.03944149613380432 -0.012112438678741455"/>
                <body name="R_B_Finger_3_2" pos="-0.0052787065505981445 -0.03944149613380432 -0.012112438678741455">
                <geom type="capsule" name="R_B_Finger_3_2_geom" size="0.05" fromto="0 0 0 -0.01556369662284851 -0.07996440678834915 -0.018579034134745598"/>
                  <body name="R_B_Finger_3_3" pos="-0.01556369662284851 -0.07996440678834915 -0.018579034134745598">
                  <geom type="capsule" name="R_B_Finger_3_3_geom" size="0.05" fromto="0 0 0 -0.007601529359817505 -0.04353569820523262 -0.018819646909832954"/>
                  </body>
                </body>
              </body>
              <body name="R_B_Finger_4_1" pos="0.006926417350769043 -0.07383957505226135 -0.13510023057460785">
              <geom type="capsule" name="R_B_Finger_4_1_geom" size="0.05" fromto="0 0 0 -0.029244542121887207 -0.02724441885948181 -0.019830886274576187"/>
                <body name="R_B_Finger_4_2" pos="-0.029244542121887207 -0.02724441885948181 -0.019830886274576187">
                <geom type="capsule" name="R_B_Finger_4_2_geom" size="0.05" fromto="0 0 0 -0.034585773944854736 -0.06896093487739563 -0.0018789730966091156"/>
                  <body name="R_B_Finger_4_3" pos="-0.034585773944854736 -0.06896093487739563 -0.0018789730966091156">
                  <geom type="capsule" name="R_B_Finger_4_3_geom" size="0.05" fromto="0 0 0 -0.02458670735359192 -0.04846162348985672 -0.017758013680577278"/>
                  </body>
                </body>
              </body>
              <body name="R_B_Finger_5_1" pos="0.006926417350769043 -0.07383957505226135 -0.13510023057460785">
              <geom type="capsule" name="R_B_Finger_5_1_geom" size="0.05" fromto="0 0 0 -0.046136558055877686 0.01041865348815918 -0.03638231009244919"/>
                <body name="R_B_Finger_5_2" pos="-0.046136558055877686 0.01041865348815918 -0.03638231009244919">
                <geom type="capsule" name="R_B_Finger_5_2_geom" size="0.05" fromto="0 0 0 -0.03107309341430664 -0.03808602690696716 -0.005154406651854515"/>
                  <body name="R_B_Finger_5_3" pos="-0.03107309341430664 -0.03808602690696716 -0.005154406651854515">
                  <geom type="capsule" name="R_B_Finger_5_3_geom" size="0.05" fromto="0 0 0 -0.023181915283203125 -0.027915887534618378 -0.007805719971656799"/>
                  </body>
                </body>
              </body>
            </body>
          </body>
        </body>
      </body>
      <body name="L_B_Paw_1" pos="0.0 -0.07109183073043823 -0.09252709150314331">
      <joint type="hinge" name="rx_L_B_Paw_1" axis="1 0 0" range="-39.99999883637168 39.99999883637168"/>
      <joint type="hinge" name="rz_L_B_Paw_1" axis="0 0 1" range="-19.99999941818584 9.99999970909292"/>
      <geom type="capsule" name="L_B_Paw_1_geom" size="0.05" fromto="0 0 0 0.12856115400791168 -0.06068772077560425 -0.1629948616027832"/>
        <body name="L_B_Paw_2" pos="0.12856115400791168 -0.06068772077560425 -0.1629948616027832">
        <joint type="hinge" name="rx_L_B_Paw_2" axis="1 0 0" range="-19.99999941818584 19.99999941818584"/>
        <joint type="hinge" name="rz_L_B_Paw_2" axis="0 0 1" range="-30.000000834826057 30.000000834826057"/>
        <geom type="capsule" name="L_B_Paw_2_geom" size="0.05" fromto="0 0 0 0.10558734834194183 -0.26967060565948486 -0.16305959224700928"/>
          <body name="L_B_Paw_3" pos="0.10558734834194183 -0.26967060565948486 -0.16305959224700928">
          <geom type="capsule" name="L_B_Paw_3_geom" size="0.05" fromto="0 0 0 -0.007300674915313721 0.27059853076934814 -0.14332720637321472"/>
            <body name="L_B_Paw_4" pos="-0.007300674915313721 0.27059853076934814 -0.14332720637321472">
            <joint type="hinge" name="rz_L_B_Paw_4" axis="0 0 1" range="-19.99999941818584 19.99999941818584"/>
            <geom type="capsule" name="L_B_Paw_4_geom" size="0.05" fromto="0 0 0 -0.006800621747970581 -0.07383954524993896 -0.13510014116764069"/>
              <body name="L_B_Finger_1_1" pos="-0.006800621747970581 -0.07383954524993896 -0.13510014116764069">
              <geom type="capsule" name="L_B_Finger_1_1_geom" size="0.05" fromto="0 0 0 -0.0506262332201004 -0.01381131261587143 -0.0339580737054348"/>
                <body name="L_B_Finger_1_2" pos="-0.0506262332201004 -0.01381131261587143 -0.0339580737054348">
                <geom type="capsule" name="L_B_Finger_1_2_geom" size="0.05" fromto="0 0 0 -0.005271017551422119 -0.025599561631679535 -0.015743747353553772"/>
                  <body name="L_B_Finger_1_3" pos="-0.005271017551422119 -0.025599561631679535 -0.015743747353553772">
                  <geom type="capsule" name="L_B_Finger_1_3_geom" size="0.05" fromto="0 0 0 -0.00330149382352829 -0.016032539308071136 -0.011576314456760883"/>
                  </body>
                </body>
              </body>
              <body name="L_B_Finger_2_1" pos="-0.006800621747970581 -0.07383954524993896 -0.13510014116764069">
              <geom type="capsule" name="L_B_Finger_2_1_geom" size="0.05" fromto="0 0 0 -0.02315250039100647 -0.04023982584476471 -0.02362186089158058"/>
                <body name="L_B_Finger_2_2" pos="-0.02315250039100647 -0.04023982584476471 -0.02362186089158058">
                <geom type="capsule" name="L_B_Finger_2_2_geom" size="0.05" fromto="0 0 0 -0.0022902637720108032 -0.06750748306512833 -8.124858140945435e-05"/>
                  <body name="L_B_Finger_2_3" pos="-0.0022902637720108032 -0.06750748306512833 -8.124858140945435e-05">
                  <geom type="capsule" name="L_B_Finger_2_3_geom" size="0.05" fromto="0 0 0 -0.0020578503608703613 -0.047204043716192245 -0.020307021215558052"/>
                  </body>
                </body>
              </body>
              <body name="L_B_Finger_3_1" pos="-0.006800621747970581 -0.07383954524993896 -0.13510014116764069">
              <geom type="capsule" name="L_B_Finger_3_1_geom" size="0.05" fromto="0 0 0 0.005278676748275757 -0.03944147378206253 -0.012112416326999664"/>
                <body name="L_B_Finger_3_2" pos="0.005278676748275757 -0.03944147378206253 -0.012112416326999664">
                <geom type="capsule" name="L_B_Finger_3_2_geom" size="0.05" fromto="0 0 0 0.015563726425170898 -0.07996444404125214 -0.018579011783003807"/>
                  <body name="L_B_Finger_3_3" pos="0.015563726425170898 -0.07996444404125214 -0.018579011783003807">
                  <geom type="capsule" name="L_B_Finger_3_3_geom" size="0.05" fromto="0 0 0 0.007601499557495117 -0.04353569447994232 -0.018819618970155716"/>
                  </body>
                </body>
              </body>
              <body name="L_B_Finger_4_1" pos="-0.006800621747970581 -0.07383954524993896 -0.13510014116764069">
              <geom type="capsule" name="L_B_Finger_4_1_geom" size="0.05" fromto="0 0 0 0.02924451231956482 -0.027244411408901215 -0.019830875098705292"/>
                <body name="L_B_Finger_4_2" pos="0.02924451231956482 -0.027244411408901215 -0.019830875098705292">
                <geom type="capsule" name="L_B_Finger_4_2_geom" size="0.05" fromto="0 0 0 0.03458578884601593 -0.06896093487739563 -0.0018789581954479218"/>
                  <body name="L_B_Finger_4_3" pos="0.03458578884601593 -0.06896093487739563 -0.0018789581954479218">
                  <geom type="capsule" name="L_B_Finger_4_3_geom" size="0.05" fromto="0 0 0 0.024586692452430725 -0.048461612313985825 -0.01775798760354519"/>
                  </body>
                </body>
              </body>
              <body name="L_B_Finger_5_1" pos="-0.006800621747970581 -0.07383954524993896 -0.13510014116764069">
              <geom type="capsule" name="L_B_Finger_5_1_geom" size="0.05" fromto="0 0 0 0.046136513352394104 0.01041865348815918 -0.036382291465997696"/>
                <body name="L_B_Finger_5_2" pos="0.046136513352394104 0.01041865348815918 -0.036382291465997696">
                <geom type="capsule" name="L_B_Finger_5_2_geom" size="0.05" fromto="0 0 0 0.03107304871082306 -0.03808602690696716 -0.005154384300112724"/>
                  <body name="L_B_Finger_5_3" pos="0.03107304871082306 -0.03808602690696716 -0.005154384300112724">
                  <geom type="capsule" name="L_B_Finger_5_3_geom" size="0.05" fromto="0 0 0 0.0231819748878479 -0.027915894985198975 -0.00780570600181818"/>
                  </body>
                </body>
              </body>
            </body>
          </body>
        </body>
      </body>
    </body>
  </worldbody>
<asset>
<texture name="grid" type="2d" builtin="checker" width="512" height="512" rgb1=".1 .2 .3" rgb2=".2 .3 .4"/>
<material name="grid" texture="grid" texrepeat="1 1" texuniform="true" reflectance=".2"/>
  </asset></mujoco>
