<mujoco model="unnamed_model">
  <compiler boundmass="0.001" boundinertia="1.0000000000000001e-09" angle="radian"/>
  <option timestep="0.001" integrator="implicitfast"/>
  <default>
    <default class="/"/>
  </default>
  <asset>
    <mesh name="Cube.001" class="/" file="Cube.001-efbd42ec691a6894f305f150aa6f0438f30cd3ad.msh"/>
    <mesh name="Cylinder.001_Brown" class="/" file="Cylinder.001_Brown-b6cf4730bfb595e6ab90ae241b2e62c5032003a2.msh"/>
    <material name="Brown" class="/" specular="0.5" shininess="0" reflectance="0" rgba="0.80000001192092896 0.80000001192092896 0.80000001192092896 1"/>
    <material name="Black" class="/" specular="0.5" shininess="0" reflectance="0" rgba="0.80000001192092896 0.80000001192092896 0.80000001192092896 1"/>
    <material name="Gray" class="/" specular="0.5" shininess="0" reflectance="0" rgba="0.80000001192092896 0.80000001192092896 0.80000001192092896 1"/>
    <material name="White" class="/" specular="0.5" shininess="0" reflectance="0" rgba="0.80000001192092896 0.80000001192092896 0.80000001192092896 1"/>
    <material name="Lightbrown" class="/" specular="0.5" shininess="0" reflectance="0" rgba="0.80000001192092896 0.80000001192092896 0.80000001192092896 1"/>
    <mesh name="Cylinder.002_Brown" class="/" file="Cylinder.002_Brown-cf283cc546743ad6c0a9034dd384f87d8134ab26.msh"/>
    <mesh name="Cylinder.003_Brown" class="/" file="Cylinder.003_Brown-e6fc80684390a171d3e446601d950ad482ae679a.msh"/>
    <mesh name="Cylinder.004_Brown" class="/" file="Cylinder.004_Brown-eb3aa13eca22b454c6cef93ab41873f38ef9c21c.msh"/>
    <mesh name="Cylinder.005_Brown" class="/" file="Cylinder.005_Brown-8def44220b49c02f71e5f2bf0b74dc6362c0f67d.msh"/>
    <mesh name="Cylinder.006_Brown" class="/" file="Cylinder.006_Brown-35cc59677d979cf39f23b47315e00a42a19b4661.msh"/>
    <mesh name="Cylinder.007_Brown" class="/" file="Cylinder.007_Brown-ea8bdf1703336e3015c2fa1b6b64a1b29a951e7b.msh"/>
    <mesh name="Cylinder.008_Brown" class="/" file="Cylinder.008_Brown-3f9b69b1512a73199c0b46a1caab7fceec30e2f6.msh"/>
    <mesh name="Cylinder.009_Brown" class="/" file="Cylinder.009_Brown-2e465c2ebb90f77161acbfff41b3825bd5ba9e3c.msh"/>
    <mesh name="Cylinder.010_Brown" class="/" file="Cylinder.010_Brown-11b4ae91d2ea2ab963e13d35f5554410b3d12944.msh"/>
    <mesh name="Cylinder.011_Brown" class="/" file="Cylinder.011_Brown-1fe6be74e00a5bbee4a9027b5866db83d3513d67.msh"/>
    <mesh name="Cylinder.012_Brown" class="/" file="Cylinder.012_Brown-85f1b8933e95b2080b7df4ca44d2a8081bca6a7f.msh"/>
    <mesh name="Cylinder.013_Brown" class="/" file="Cylinder.013_Brown-e2f1acbe008f6730a8b645b60872500830c09212.msh"/>
    <mesh name="Cylinder.014_Brown" class="/" file="Cylinder.014_Brown-5b490f72de9f0b77abb770395b32c63bca01fbe7.msh"/>
    <mesh name="Cylinder.015_Brown" class="/" file="Cylinder.015_Brown-0572f51260a5069681ad57dbec312fb31bcdc871.msh"/>
    <mesh name="Cylinder.016_Brown" class="/" file="Cylinder.016_Brown-11300c97f63723330782df11aabbde206e73968c.msh"/>
  </asset>
  <worldbody>
    <body name="Dog" pos="0 0 0" quat="1 -8.1460335366045911e-08 0 0">
      <freejoint name="//unnamed_joint_0"/>
      <body name="Root_Dog" pos="-1.3155799649666733e-07 0.40374860167503357 0.78592765331268311" quat="1.7555998965690378e-07 -1.2416731465236808e-07 0.13849811255931854 -0.99036270380020142">
        <body name="Back_Dog" pos="2.8421709430404007e-14 0.050057247281074524 -3.7252938511755929e-08" quat="0.38992375135421753 -0.92084711790084839 -6.5392960379995202e-08 3.4337031706854759e-07">
          <body name="Tail_Dog" pos="2.8421709430404007e-14 0.20064634084701538 -5.9604765567655704e-08" quat="0.95999372005462646 0.28002145886421204 1.6747351594403881e-07 -1.0252696114321225e-07"/>
        </body>
        <body name="Back.001_Dog" pos="2.8421709430404007e-14 0.050057247281074524 -3.7252938511755929e-08" quat="0.9935380220413208 0.11340750008821487 0.00063551263883709908 -0.004543681163340807">
          <joint name="rx_Back.001_Dog" class="/" type="hinge" pos="0 0 0" axis="1 0 0" limited="true" stiffness="0.01" range="-9.9999997090929202 4.9999998545464601" damping="0.01"/>
          <joint name="ry_Back.001_Dog" class="/" type="hinge" pos="0 0 0" axis="0 1 0" limited="true" stiffness="0.01" range="-1.9999999845072665 1.9999999845072665" damping="0.01"/>
          <joint name="rz_Back.001_Dog" class="/" type="hinge" pos="0 0 0" axis="0 0 1" limited="true" stiffness="0.01" range="-9.9999997090929202 9.9999997090929202" damping="0.01"/>
          <body name="Back.002_Dog" pos="1.7462298274040222e-10 0.24536779522895813 1.0591418231342686e-07" quat="0.99980896711349487 0.015225116163492203 -1.5501202142331749e-05 0.012260881252586842">
            <joint name="rx_Back.002_Dog" class="/" type="hinge" pos="0 0 0" axis="1 0 0" limited="true" stiffness="0.01" range="-9.9999997090929202 4.9999998545464601" damping="0.01"/>
            <joint name="ry_Back.002_Dog" class="/" type="hinge" pos="0 0 0" axis="0 1 0" limited="true" stiffness="0.01" range="-1.9999999845072665 1.9999999845072665" damping="0.01"/>
            <joint name="rz_Back.002_Dog" class="/" type="hinge" pos="0 0 0" axis="0 0 1" limited="true" stiffness="0.01" range="-9.9999997090929202 9.9999997090929202" damping="0.01"/>
            <body name="Back.003_Dog" pos="3.0391689165298885e-11 0.1466849148273468 -5.6639283485537817e-08" quat="0.99774444103240967 -0.066687397658824921 0.00036448502214625478 -0.007664849516004324">
              <joint name="rx_Back.003_Dog" class="/" type="hinge" pos="0 0 0" axis="1 0 0" limited="true" stiffness="0.01" range="-9.9999997090929202 4.9999998545464601" damping="0.01"/>
              <joint name="ry_Back.003_Dog" class="/" type="hinge" pos="0 0 0" axis="0 1 0" limited="true" stiffness="0.01" range="-1.9999999845072665 1.9999999845072665" damping="0.01"/>
              <joint name="rz_Back.003_Dog" class="/" type="hinge" pos="0 0 0" axis="0 0 1" limited="true" stiffness="0.01" range="-9.9999997090929202 9.9999997090929202" damping="0.01"/>
              <body name="Back.004_Dog" pos="-7.1054273576010019e-15 0.15391294658184052 2.0489098417897367e-08" quat="0.9820854663848877 0.18843615055084229 -6.6270189336137264e-08 -6.4240177621854855e-09">
                <joint name="rx_Back.004_Dog" class="/" type="hinge" pos="0 0 0" axis="1 0 0" limited="true" stiffness="0.01" range="-9.9999997090929202 4.9999998545464601" damping="0.01"/>
                <joint name="ry_Back.004_Dog" class="/" type="hinge" pos="0 0 0" axis="0 1 0" limited="true" stiffness="0.01" range="-1.9999999845072665 1.9999999845072665" damping="0.01"/>
                <joint name="rz_Back.004_Dog" class="/" type="hinge" pos="0 0 0" axis="0 0 1" limited="true" stiffness="0.01" range="-9.9999997090929202 9.9999997090929202" damping="0.01"/>
                <body name="Neck_Dog" pos="-1.4210854715202004e-14 0.16253991425037384 2.9802325940408991e-08" quat="0.9976351261138916 0.068732470273971558 7.4140253047971783e-08 -2.0161368130544588e-09">
                  <body name="Neck.001_Dog" pos="1.0658141036401503e-14 0.10233661532402039 -1.4901184286486568e-08" quat="0.99622422456741333 -0.086817577481269836 7.0668725982159231e-08 1.6380680278871296e-07">
                    <body name="Head_Dog" pos="-4.2632564145606011e-14 0.074453845620155334 5.9604602142826479e-08" quat="0.99998718500137329 -0.0050590578466653824 3.7592218404824962e-07 -2.36465595548907e-07">
                      <body name="Head.001_Dog" pos="-7.1054273576010019e-14 0.21294404566287994 1.4900933820172213e-08" quat="0.98828673362731934 -0.15260836482048035 -4.7967796490411274e-07 -5.9781655181723181e-09"/>
                      <body name="Jaw_Dog" pos="-7.1054273576010019e-14 0.21294404566287994 1.4900933820172213e-08" quat="0.7257922887802124 -0.68791389465332031 -3.6271799785936309e-07 -2.759460926426982e-07">
                        <body name="Mouth_Dog" pos="2.6645352591003757e-15 0.13153044879436493 5.9604715829664201e-08" quat="0.84336358308792114 0.53734332323074341 -3.4634840773151154e-08 -9.8807024784264286e-09"/>
                      </body>
                    </body>
                    <body name="EarLeft_Dog" pos="-4.2632564145606011e-14 0.074453845620155334 5.9604602142826479e-08" quat="0.89691215753555298 0.1214621439576149 0.31632483005523682 0.28413742780685425">
                      <body name="EarLeft.001_Dog" pos="-3.3527612686157227e-08 0.21727709472179413 -4.4703483581542969e-08" quat="0.97415435314178467 0.15373334288597107 0.078816182911396027 0.14552432298660278"/>
                    </body>
                    <body name="EarRight_Dog" pos="-4.2632564145606011e-14 0.074453845620155334 5.9604602142826479e-08" quat="0.89444410800933838 0.11437089741230011 -0.31304097175598145 -0.29815155267715454">
                      <body name="EarRight.001_Dog" pos="-2.6077032089233398e-08 0.22081887722015381 -9.6857547760009766e-08" quat="0.94730114936828613 0.30010837316513062 -0.098176486790180206 -0.054008059203624725"/>
                    </body>
                  </body>
                </body>
                <body name="ShoulderRight_Dog" pos="-1.4210854715202004e-14 0.16253991425037384 2.9802325940408991e-08" quat="0.77706080675125122 -0.23402343690395355 0.18060174584388733 -0.55569106340408325">
                  <body name="ArmRight_Dog" pos="5.9604644775390625e-08 0.10946473479270935 4.7497451305389404e-08" quat="0.88028371334075928 -0.44014778733253479 0.047546938061714172 -0.17061616480350494">
                    <joint name="rx_ArmRight_Dog" class="/" type="hinge" pos="0 0 0" axis="1 0 0" limited="true" stiffness="0.01" range="-9.9999997090929202 30.000000834826057" damping="0.01"/>
                    <joint name="ry_ArmRight_Dog" class="/" type="hinge" pos="0 0 0" axis="0 1 0" limited="true" stiffness="0.01" range="-9.9999997090929202 9.9999997090929202" damping="0.01"/>
                    <joint name="rz_ArmRight_Dog" class="/" type="hinge" pos="0 0 0" axis="0 0 1" limited="true" stiffness="0.01" range="-60.000001669652114 60.000001669652114" damping="0.01"/>
                    <body name="ArmRight.001_Dog" pos="-1.9790604710578918e-08 0.20932172238826752 1.6763806343078613e-08" quat="0.99755704402923584 0.069699913263320923 -0.00010819204908329993 -0.0046784821897745132">
                      <joint name="rx_ArmRight.001_Dog" class="/" type="hinge" pos="0 0 0" axis="1 0 0" limited="true" stiffness="0.01" range="-19.99999941818584 45.00000125223908" damping="0.01"/>
                      <joint name="ry_ArmRight.001_Dog" class="/" type="hinge" pos="0 0 0" axis="0 1 0" limited="true" stiffness="0.01" range="-9.9999997090929202 9.9999997090929202" damping="0.01"/>
                      <joint name="rz_ArmRight.001_Dog" class="/" type="hinge" pos="0 0 0" axis="0 0 1" limited="true" stiffness="0.01" range="-60.000001669652114 79.999997672743362" damping="0.01"/>
                      <body name="ArmRight.002_Dog" pos="-2.0489096641540527e-08 0.062612548470497131 -3.7252902984619141e-09" quat="0.99362373352050781 -0.11249096691608429 -0.00027763639809563756 0.0075937304645776749">
                        <body name="ArmRight.003_Dog" pos="-4.4837804580311058e-09 0.1010371521115303 -7.5252870601616451e-09" quat="0.98458600044250488 -0.074383214116096497 0.013699064962565899 -0.1577019989490509">
                          <body name="ArmRight.004_Dog" pos="1.7229467630386353e-08 0.16071483492851257 -6.0535967350006104e-09" quat="0.98288679122924805 0.096679747104644775 -0.0092002414166927338 0.15653100609779358">
                            <body name="ArmRight.005_Dog" pos="9.6915755420923233e-09 0.14895226061344147 -6.7520886659622192e-09" quat="0.73899692296981812 0.030089352279901505 0.012666435912251472 0.67291736602783203">
                              <joint name="rz_ArmRight.005_Dog" class="/" type="hinge" pos="0 0 0" axis="0 0 1" limited="true" stiffness="0.01" range="-39.999998836371681 30.000000834826057" damping="0.01"/>
                              <geom name="Cylinder.001_Brown" class="/" type="mesh" material="Brown" pos="0.069133862853050232 -0.33272328972816467 -0.10865456610918045" quat="0.45847949385643005 -0.50312310457229614 0.49342820048332214 0.54147356748580933" mesh="Cylinder.003_Brown"/>
                            </body>
                            <geom name="Cylinder.008_Brown" class="/" type="mesh" material="Brown" pos="0.33073019981384277 0.18994858860969543 -0.12738634645938873" quat="0.016663134098052979 0.68318700790405273 -0.015595883131027222 -0.72988677024841309" mesh="Cylinder.010_Brown"/>
                          </body>
                          <geom name="Cylinder.010_Brown" class="/" type="mesh" material="Brown" pos="0.25412937998771667 0.46355998516082764 -0.073438942432403564" quat="0.064434126019477844 0.68226319551467896 0.16202311217784882 -0.71000957489013672" mesh="Cylinder.012_Brown"/>
                        </body>
                      </body>
                      <geom name="Cylinder.013_Brown" class="/" type="mesh" material="Brown" pos="0.3742695152759552 0.47150883078575134 -0.24002848565578461" quat="0.082354679703712463 0.67862820625305176 -0.077002808451652527 -0.7257767915725708" mesh="Cylinder.015_Brown"/>
                    </body>
                  </body>
                </body>
                <body name="ShoulderLeft_Dog" pos="2.258690585676959e-07 0.16253991425037384 2.9802318834981634e-08" quat="0.77706098556518555 -0.23402352631092072 -0.18060161173343658 0.55569082498550415">
                  <body name="ArmLeft_Dog" pos="-3.166496753692627e-08 0.10946474224328995 2.2351741790771484e-08" quat="0.88028371334075928 -0.44014778733253479 -0.047546960413455963 0.17061610519886017">
                    <joint name="rx_ArmLeft_Dog" class="/" type="hinge" pos="0 0 0" axis="1 0 0" limited="true" stiffness="0.01" range="-9.9999997090929202 30.000000834826057" damping="0.01"/>
                    <joint name="ry_ArmLeft_Dog" class="/" type="hinge" pos="0 0 0" axis="0 1 0" limited="true" stiffness="0.01" range="-9.9999997090929202 9.9999997090929202" damping="0.01"/>
                    <joint name="rz_ArmLeft_Dog" class="/" type="hinge" pos="0 0 0" axis="0 0 1" limited="true" stiffness="0.01" range="-60.000001669652114 60.000001669652114" damping="0.01"/>
                    <body name="ArmLeft.001_Dog" pos="1.9557774066925049e-08 0.20932164788246155 1.862645149230957e-09" quat="0.99755704402923584 0.069699861109256744 0.00010819017916219309 0.004678492434322834">
                      <joint name="rx_ArmLeft.001_Dog" class="/" type="hinge" pos="0 0 0" axis="1 0 0" limited="true" stiffness="0.01" range="-19.99999941818584 45.00000125223908" damping="0.01"/>
                      <joint name="ry_ArmLeft.001_Dog" class="/" type="hinge" pos="0 0 0" axis="0 1 0" limited="true" stiffness="0.01" range="-9.9999997090929202 9.9999997090929202" damping="0.01"/>
                      <joint name="rz_ArmLeft.001_Dog" class="/" type="hinge" pos="0 0 0" axis="0 0 1" limited="true" stiffness="0.01" range="-60.000001669652114 79.999997672743362" damping="0.01"/>
                      <body name="ArmLeft.002_Dog" pos="1.1175870895385742e-08 0.062612526118755341 1.6763806343078613e-08" quat="0.99362367391586304 -0.11249101161956787 0.0002776283654384315 -0.0075937351211905479">
                        <body name="ArmLeft.003_Dog" pos="-2.9654124489297828e-08 0.1010371670126915 1.2985509556528996e-08" quat="0.98458600044250488 -0.07438322901725769 -0.013699077069759369 0.1577020138502121">
                          <body name="ArmLeft.004_Dog" pos="-2.514570951461792e-08 0.16071480512619019 -6.9849193096160889e-09" quat="0.98288679122924805 0.096679769456386566 0.0092002479359507561 -0.15653099119663239">
                            <body name="ArmLeft.005_Dog" pos="-1.6632839106023312e-08 0.1489521712064743 -9.7788870334625244e-09" quat="0.73899686336517334 0.030089404433965683 -0.012666424736380577 -0.67291748523712158">
                              <joint name="rz_ArmLeft.005_Dog" class="/" type="hinge" pos="0 0 0" axis="0 0 1" limited="true" stiffness="0.01" range="-39.999998836371681 30.000000834826057" damping="0.01"/>
                              <geom name="ArmLeft.005_Brown" class="/" type="mesh" material="Brown" pos="-0.069240137934684753 -0.33468759059906006 -0.10272111743688583" quat="0.46060538291931152 -0.50802570581436157 -0.49400356411933899 -0.53452271223068237" mesh="Cylinder.002_Brown"/>
                            </body>
                            <geom name="Cylinder.009_Brown" class="/" type="mesh" material="Brown" pos="-0.33072984218597412 0.18994790315628052 -0.12738603353500366" quat="0.016663067042827606 0.68318676948547363 0.015596082434058189 0.72988694906234741" mesh="Cylinder.011_Brown"/>
                          </body>
                          <geom name="Cylinder.011_Brown" class="/" type="mesh" material="Brown" pos="-0.25412940979003906 0.46355918049812317 -0.073438778519630432" quat="0.064434148371219635 0.68226289749145508 -0.16202270984649658 0.71000993251800537" mesh="Cylinder.013_Brown"/>
                        </body>
                      </body>
                      <geom name="Cylinder.012_Brown" class="/" type="mesh" material="Brown" pos="-0.37426945567131042 0.4715086817741394 -0.24002841114997864" quat="0.08235478401184082 0.67862802743911743 0.077002964913845062 0.72577691078186035" mesh="Cylinder.014_Brown"/>
                    </body>
                  </body>
                </body>
              </body>
            </body>
            <geom name="Cylinder.014_Brown" class="/" type="mesh" material="Brown" pos="-9.6144511189777404e-05 0.12585538625717163 -0.75741368532180786" quat="0.005582678597420454 0.0052649108693003654 0.69993394613265991 0.71416634321212769" mesh="Cylinder.016_Brown"/>
          </body>
          <geom name="Cylinder_Brown" class="/" type="mesh" material="Brown" pos="-0.0034410813823342323 0.39418396353721619 -0.7532305121421814" quat="0.0032439953647553921 0.0032439767383038998 -0.68899142742156982 -0.72475498914718628" mesh="Cylinder.001_Brown"/>
        </body>
        <body name="HipRight_Dog" pos="2.8421709430404007e-14 0.050057247281074524 -3.7252938511755929e-08" quat="0.76658600568771362 -0.17536850273609161 0.28863424062728882 -0.54615211486816406">
          <body name="FootRight_Dog" pos="1.9557774066925049e-08 0.19679707288742065 4.4703483581542969e-08" quat="0.88332659006118774 -0.46503227949142456 -0.046054661273956299 -0.036853201687335968">
            <joint name="rx_FootRight_Dog" class="/" type="hinge" pos="0 0 0" axis="1 0 0" limited="true" stiffness="0.01" range="-19.99999941818584 30.000000834826057" damping="0.01"/>
            <joint name="ry_FootRight_Dog" class="/" type="hinge" pos="0 0 0" axis="0 1 0" limited="true" stiffness="0.01" range="-9.9999997090929202 19.99999941818584" damping="0.01"/>
            <joint name="rz_FootRight_Dog" class="/" type="hinge" pos="0 0 0" axis="0 0 1" limited="true" stiffness="0.01" range="-60.000001669652114 79.999997672743362" damping="0.01"/>
            <body name="FootRight.001_Dog" pos="-7.4505805969238281e-09 0.21030314266681671 5.5879354476928711e-09" quat="0.89712107181549072 -0.10814347863197327 -0.0088259810581803322 -0.42825323343276978">
              <body name="FootRight.002_Dog" pos="-2.6077032089233398e-08 0.022834733128547668 2.2351741790771484e-08" quat="0.89604842662811279 0.15411113202571869 0.00053236348321661353 0.41634926199913025">
                <body name="FootRight.003_Dog" pos="1.4901161193847656e-08 0.15161098539829254 -1.4901161193847656e-08" quat="0.96641802787780762 -0.21825908124446869 0.040827319025993347 -0.12935346364974976">
                  <body name="FootRight.004_Dog" pos="4.0978193283081055e-08 0.044760487973690033 3.7252902984619141e-09" quat="0.99816572666168213 0.057132933288812637 -7.7421238529495895e-05 -0.020026892423629761">
                    <joint name="rx_FootRight.004_Dog" class="/" type="hinge" pos="0 0 0" axis="1 0 0" limited="true" stiffness="0.01" range="-9.9999997090929202 19.99999941818584" damping="0.01"/>
                    <joint name="ry_FootRight.004_Dog" class="/" type="hinge" pos="0 0 0" axis="0 1 0" limited="true" stiffness="0.01" range="-19.99999941818584 9.9999997090929202" damping="0.01"/>
                    <joint name="rz_FootRight.004_Dog" class="/" type="hinge" pos="0 0 0" axis="0 0 1" limited="true" stiffness="0.01" range="-100.0000005060238 9.9999997090929202" damping="0.01"/>
                    <body name="FootRight.005_Dog" pos="3.7252902984619141e-09 0.043279170989990234 -3.7252902984619141e-09" quat="0.95833289623260498 0.18451139330863953 -0.034644037485122681 0.21529866755008698">
                      <body name="FootRight.006_Dog" pos="3.6545074522109644e-08 0.11480032652616501 -1.7229215387715158e-08" quat="0.99522489309310913 0.033581074327230453 6.058814688003622e-05 0.09165036678314209">
                        <body name="FootRight.007_Dog" pos="-1.1641532182693481e-08 0.049606718122959137 -6.9849193096160889e-10" quat="0.77274948358535767 0.21865981817245483 -0.00044152975897304714 0.59585738182067871">
                          <joint name="rz_FootRight.007_Dog" class="/" type="hinge" pos="0 0 0" axis="0 0 1" limited="true" stiffness="0.01" range="-30.000000834826057 30.000000834826057" damping="0.01"/>
                          <geom name="Cylinder.002_Brown" class="/" type="mesh" material="Brown" pos="-0.00018502183957025409 0.42813757061958313 -0.11179604381322861" quat="0.40464809536933899 -0.40464869141578674 0.5798795223236084 0.57987779378890991" mesh="Cylinder.004_Brown"/>
                        </body>
                      </body>
                      <geom name="Cylinder.004_Brown" class="/" type="mesh" material="Brown" pos="-0.44717127084732056 0.20186047255992889 0.052046891301870346" quat="6.844746849310468e-07 -0.57267779111862183 -6.1110620208637556e-07 0.81978058815002441" mesh="Cylinder.006_Brown"/>
                    </body>
                  </body>
                </body>
                <geom name="Cylinder.006_Brown" class="/" type="mesh" material="Brown" pos="-0.44673261046409607 0.3684055507183075 0.027988765388727188" quat="0.039976697415113449 0.57019007205963135 0.057390850037336349 -0.81853002309799194" mesh="Cylinder.008_Brown"/>
              </body>
            </body>
          </body>
        </body>
        <body name="HipLeft_Dog" pos="-2.3174601437858655e-07 0.050057247281074524 -3.7252867457482353e-08" quat="0.76658624410629272 -0.17536845803260803 -0.28863388299942017 0.54615193605422974">
          <body name="FootLeft_Dog" pos="1.5832483768463135e-08 0.19679710268974304 -7.4505805969238281e-09" quat="0.88332653045654297 -0.46503230929374695 0.04605458676815033 0.036853160709142685">
            <joint name="rx_FootLeft_Dog" class="/" type="hinge" pos="0 0 0" axis="1 0 0" limited="true" stiffness="0.01" range="-19.99999941818584 30.000000834826057" damping="0.01"/>
            <joint name="ry_FootLeft_Dog" class="/" type="hinge" pos="0 0 0" axis="0 1 0" limited="true" stiffness="0.01" range="-9.9999997090929202 19.99999941818584" damping="0.01"/>
            <joint name="rz_FootLeft_Dog" class="/" type="hinge" pos="0 0 0" axis="0 0 1" limited="true" stiffness="0.01" range="-60.000001669652114 79.999997672743362" damping="0.01"/>
            <body name="FootLeft.001_Dog" pos="-1.862645149230957e-08 0.21030306816101074 5.5879354476928711e-09" quat="0.8971211314201355 -0.10814344137907028 0.0088260453194379807 0.42825326323509216">
              <body name="FootLeft.002_Dog" pos="2.6077032089233398e-08 0.022834768518805504 2.9802322387695312e-08" quat="0.89604848623275757 0.15411107242107391 -0.00053247151663526893 -0.41634920239448547">
                <body name="FootLeft.003_Dog" pos="-5.2154064178466797e-08 0.15161100029945374 -8.3819031715393066e-09" quat="0.96641802787780762 -0.2182590663433075 -0.040827304124832153 0.12935349345207214">
                  <body name="FootLeft.004_Dog" pos="-1.4901161193847656e-08 0.044760461896657944 1.1175870895385742e-08" quat="0.99816566705703735 0.057132977992296219 7.7415759733412415e-05 0.020026868209242821">
                    <joint name="rx_FootLeft.004_Dog" class="/" type="hinge" pos="0 0 0" axis="1 0 0" limited="true" stiffness="0.01" range="-9.9999997090929202 19.99999941818584" damping="0.01"/>
                    <joint name="ry_FootLeft.004_Dog" class="/" type="hinge" pos="0 0 0" axis="0 1 0" limited="true" stiffness="0.01" range="-19.99999941818584 9.9999997090929202" damping="0.01"/>
                    <joint name="rz_FootLeft.004_Dog" class="/" type="hinge" pos="0 0 0" axis="0 0 1" limited="true" stiffness="0.01" range="-100.0000005060238 9.9999997090929202" damping="0.01"/>
                    <body name="FootLeft.005_Dog" pos="3.3527612686157227e-08 0.043279178440570831 3.7252902984619141e-09" quat="0.95833289623260498 0.18451130390167236 0.034644041210412979 -0.21529863774776459">
                      <body name="FootLeft.006_Dog" pos="-6.1962879271959537e-08 0.11480031162500381 -1.7390902939951047e-08" quat="0.99522489309310913 0.033581074327230453 -6.0564048908418044e-05 -0.091650381684303284">
                        <body name="FootLeft.007_Dog" pos="-1.0244548320770264e-08 0.049606744199991226 9.3132257461547852e-09" quat="0.77274936437606812 0.21865986287593842 0.00044163587153889239 -0.59585750102996826">
                          <joint name="rz_FootLeft.007_Dog" class="/" type="hinge" pos="0 0 0" axis="0 0 1" limited="true" stiffness="0.01" range="-30.000000834826057 30.000000834826057" damping="0.01"/>
                          <geom name="Cylinder.003_Brown" class="/" type="mesh" material="Brown" pos="0.0014824558747932315 0.4260421097278595 -0.11510635167360306" quat="0.40150284767150879 -0.40713769197463989 -0.58225494623184204 -0.57793843746185303" mesh="Cylinder.005_Brown"/>
                        </body>
                      </body>
                      <geom name="Cylinder.005_Brown" class="/" type="mesh" material="Brown" pos="0.44642657041549683 0.2017846405506134 0.047987665981054306" quat="0.00032964066485874355 0.57677996158599854 0.00050072942394763231 0.81689935922622681" mesh="Cylinder.007_Brown"/>
                    </body>
                  </body>
                </body>
                <geom name="Cylinder.007_Brown" class="/" type="mesh" material="Brown" pos="0.44601446390151978 0.36863785982131958 0.024048512801527977" quat="0.039987578988075256 0.57422274351119995 -0.057103343307971954 0.81572568416595459" mesh="Cylinder.009_Brown"/>
              </body>
            </body>
          </body>
        </body>
      </body>
    </body>
    <geom name="Cube" class="/" type="mesh" pos="0 0 -0.5160096287727356" quat="1 0 0 0" mesh="Cube.001"/>
  </worldbody>
  <tendon>
    <fixed name="back_x" class="/" limited="true" range="-1 0">
      <joint joint="rx_Back.001_Dog" coef="1"/>
      <joint joint="rx_Back.002_Dog" coef="1"/>
      <joint joint="rx_Back.003_Dog" coef="1"/>
      <joint joint="rx_Back.004_Dog" coef="1"/>
    </fixed>
    <fixed name="back_z" class="/">
      <joint joint="rz_Back.001_Dog" coef="1"/>
      <joint joint="rz_Back.002_Dog" coef="1"/>
      <joint joint="rz_Back.003_Dog" coef="1"/>
      <joint joint="rz_Back.004_Dog" coef="1"/>
    </fixed>
  </tendon>
  <actuator>
    <motor name="ry_Back.001_Dog_motor" class="/" gear="100" joint="ry_Back.001_Dog"/>
    <motor name="ry_Back.002_Dog_motor" class="/" gear="100" joint="ry_Back.002_Dog"/>
    <motor name="ry_Back.003_Dog_motor" class="/" gear="100" joint="ry_Back.003_Dog"/>
    <motor name="ry_Back.004_Dog_motor" class="/" gear="100" joint="ry_Back.004_Dog"/>
    <motor name="rx_ArmRight_Dog_motor" class="/" gear="100" joint="rx_ArmRight_Dog"/>
    <motor name="ry_ArmRight_Dog_motor" class="/" gear="100" joint="ry_ArmRight_Dog"/>
    <motor name="rz_ArmRight_Dog_motor" class="/" gear="100" joint="rz_ArmRight_Dog"/>
    <motor name="rx_ArmRight.001_Dog_motor" class="/" gear="100" joint="rx_ArmRight.001_Dog"/>
    <motor name="ry_ArmRight.001_Dog_motor" class="/" gear="100" joint="ry_ArmRight.001_Dog"/>
    <motor name="rz_ArmRight.001_Dog_motor" class="/" gear="100" joint="rz_ArmRight.001_Dog"/>
    <motor name="rz_ArmRight.005_Dog_motor" class="/" gear="100" joint="rz_ArmRight.005_Dog"/>
    <motor name="rx_ArmLeft_Dog_motor" class="/" gear="100" joint="rx_ArmLeft_Dog"/>
    <motor name="ry_ArmLeft_Dog_motor" class="/" gear="100" joint="ry_ArmLeft_Dog"/>
    <motor name="rz_ArmLeft_Dog_motor" class="/" gear="100" joint="rz_ArmLeft_Dog"/>
    <motor name="rx_ArmLeft.001_Dog_motor" class="/" gear="100" joint="rx_ArmLeft.001_Dog"/>
    <motor name="ry_ArmLeft.001_Dog_motor" class="/" gear="100" joint="ry_ArmLeft.001_Dog"/>
    <motor name="rz_ArmLeft.001_Dog_motor" class="/" gear="100" joint="rz_ArmLeft.001_Dog"/>
    <motor name="rz_ArmLeft.005_Dog_motor" class="/" gear="100" joint="rz_ArmLeft.005_Dog"/>
    <motor name="rx_FootRight_Dog_motor" class="/" gear="100" joint="rx_FootRight_Dog"/>
    <motor name="ry_FootRight_Dog_motor" class="/" gear="100" joint="ry_FootRight_Dog"/>
    <motor name="rz_FootRight_Dog_motor" class="/" gear="100" joint="rz_FootRight_Dog"/>
    <motor name="rx_FootRight.004_Dog_motor" class="/" gear="100" joint="rx_FootRight.004_Dog"/>
    <motor name="ry_FootRight.004_Dog_motor" class="/" gear="100" joint="ry_FootRight.004_Dog"/>
    <motor name="rz_FootRight.004_Dog_motor" class="/" gear="100" joint="rz_FootRight.004_Dog"/>
    <motor name="rz_FootRight.007_Dog_motor" class="/" gear="100" joint="rz_FootRight.007_Dog"/>
    <motor name="rx_FootLeft_Dog_motor" class="/" gear="100" joint="rx_FootLeft_Dog"/>
    <motor name="ry_FootLeft_Dog_motor" class="/" gear="100" joint="ry_FootLeft_Dog"/>
    <motor name="rz_FootLeft_Dog_motor" class="/" gear="100" joint="rz_FootLeft_Dog"/>
    <motor name="rx_FootLeft.004_Dog_motor" class="/" gear="100" joint="rx_FootLeft.004_Dog"/>
    <motor name="ry_FootLeft.004_Dog_motor" class="/" gear="100" joint="ry_FootLeft.004_Dog"/>
    <motor name="rz_FootLeft.004_Dog_motor" class="/" gear="100" joint="rz_FootLeft.004_Dog"/>
    <motor name="rz_FootLeft.007_Dog_motor" class="/" gear="100" joint="rz_FootLeft.007_Dog"/>
    <general name="back_x_motor" class="/" tendon="back_x" gainprm="5"/>
    <general name="back_z_motor" class="/" tendon="back_z" gainprm="5"/>
  </actuator>
</mujoco>
