<mujoco>
  <compiler meshdir="./mesh"/>
  <worldbody>
      <geom name="floor" size="0 0 .05" type="plane" material="grid" condim="3"/>
    <body name="Back_1" pos="0.0002118779084412381 2.3454556465148926 2.9882309436798096" quat="1.0 0.0 0.0 0.0">
    <joint type="free"/>
    <geom type="capsule" name="Back_1_geom" size="0.1" fromto="0 0 0 0.0 -0.30201101303100586 -0.2969825267791748"/>
      <body name="Back_2" pos="0.0 -0.30201101303100586 -0.2969825267791748" quat="1.0 0.0 0.0 0.0">
      <joint type="hinge" name="rx_Back_2" axis="1 0 0" range="-9.99999970909292 9.99999970909292"/>
      <joint type="hinge" name="rz_Back_2" axis="0 0 1" range="-9.99999970909292 6.000000166965211"/>
      <geom type="capsule" name="Back_2_geom" size="0.1" fromto="0 0 0 0.0 -0.8788895606994629 0.4750666618347168"/>
        <body name="Back_3" pos="0.0 -0.8788895606994629 0.4750666618347168" quat="1.0 0.0 0.0 0.0">
        <joint type="hinge" name="rx_Back_3" axis="1 0 0" range="-9.99999970909292 9.99999970909292"/>
        <joint type="hinge" name="rz_Back_3" axis="0 0 1" range="-9.99999970909292 6.000000166965211"/>
        <geom type="capsule" name="Back_3_geom" size="0.1" fromto="0 0 0 0.0 -0.967792272567749 0.08790779113769531"/>
          <body name="Back_4" pos="0.0 -0.967792272567749 0.08790779113769531" quat="1.0 0.0 0.0 0.0">
          <joint type="hinge" name="rx_Back_4" axis="1 0 0" range="-9.99999970909292 9.99999970909292"/>
          <joint type="hinge" name="rz_Back_4" axis="0 0 1" range="-9.99999970909292 6.000000166965211"/>
          <geom type="capsule" name="Back_4_geom" size="0.1" fromto="0 0 0 0.0 -0.9245492815971375 -0.10741996765136719"/>
            <body name="Back_5" pos="0.0 -0.9245492815971375 -0.10741996765136719" quat="1.0 0.0 0.0 0.0">
            <joint type="hinge" name="rx_Back_5" axis="1 0 0" range="-9.99999970909292 9.99999970909292"/>
            <joint type="hinge" name="rz_Back_5" axis="0 0 1" range="-9.99999970909292 6.000000166965211"/>
            <geom type="capsule" name="Back_5_geom" size="0.1" fromto="0 0 0 0.0 -0.8218173980712891 -0.23150253295898438"/>
              <body name="Back_6" pos="0.0 -0.8218173980712891 -0.23150253295898438" quat="1.0 0.0 0.0 0.0">
              <joint type="hinge" name="rx_Back_6" axis="1 0 0" range="-9.99999970909292 9.99999970909292"/>
              <joint type="hinge" name="rz_Back_6" axis="0 0 1" range="-9.99999970909292 6.000000166965211"/>
              <geom type="capsule" name="Back_6_geom" size="0.1" fromto="0 0 0 0.0 -0.7133957147598267 -0.37315845489501953"/>
                <body name="Neck" pos="0.0 -0.7133957147598267 -0.37315845489501953" quat="1.0 0.0 0.0 0.0">
                <geom type="capsule" name="Neck_geom" size="0.1" fromto="0 0 0 0.0 -0.30498695373535156 -0.01731586456298828"/>
                  <body name="Head" pos="0.0 -0.30498695373535156 -0.01731586456298828" quat="1.0 0.0 0.0 0.0">
                  <geom type="capsule" name="Head_geom" size="0.1" fromto="0 0 0 -0.010121570900082588 -0.9325973987579346 -0.19159269332885742"/>
                    <body name="L_Ear_1" pos="-0.010121570900082588 -0.9325973987579346 -0.19159269332885742" quat="1.0 0.0 0.0 0.0">
                    <geom type="capsule" name="L_Ear_1_geom" size="0.1" fromto="0 0 0 0.3327448070049286 0.35448598861694336 0.08612966537475586"/>
                      <body name="L_Ear_2" pos="0.3327448070049286 0.35448598861694336 0.08612966537475586" quat="1.0 0.0 0.0 0.0">
                      <geom type="capsule" name="L_Ear_2_geom" size="0.1" fromto="0 0 0 0.40737244486808777 0.22723960876464844 0.034210205078125"/>
                        <body name="L_Ear_3" pos="0.40737244486808777 0.22723960876464844 0.034210205078125" quat="1.0 0.0 0.0 0.0">
                        <geom type="capsule" name="L_Ear_3_geom" size="0.1" fromto="0 0 0 0.1545829176902771 0.08008956909179688 0.09064579010009766"/>
                        </body>
                      </body>
                    </body>
                    <body name="Jaw_1" pos="-0.010121570900082588 -0.9325973987579346 -0.19159269332885742" quat="1.0 0.0 0.0 0.0">
                    <geom type="capsule" name="Jaw_1_geom" size="0.1" fromto="0 0 0 0.010121571831405163 -0.4203355312347412 -0.9227763414382935"/>
                      <body name="Jaw_2" pos="0.010121571831405163 -0.4203355312347412 -0.9227763414382935" quat="1.0 0.0 0.0 0.0">
                      <geom type="capsule" name="Jaw_2_geom" size="0.1" fromto="0 0 0 0.009812356904149055 -0.4501652717590332 -0.06295669078826904"/>
                      </body>
                    </body>
                    <body name="R_Ear_1" pos="-0.010121570900082588 -0.9325973987579346 -0.19159269332885742" quat="1.0 0.0 0.0 0.0">
                    <geom type="capsule" name="R_Ear_1_geom" size="0.1" fromto="0 0 0 -0.3125016987323761 0.35448598861694336 0.08612966537475586"/>
                      <body name="R_Ear_2" pos="-0.3125016987323761 0.35448598861694336 0.08612966537475586" quat="1.0 0.0 0.0 0.0">
                      <geom type="capsule" name="R_Ear_2_geom" size="0.1" fromto="0 0 0 -0.4073724150657654 0.22723984718322754 0.034210205078125"/>
                        <body name="R_Ear_3" pos="-0.4073724150657654 0.22723984718322754 0.034210205078125" quat="1.0 0.0 0.0 0.0">
                        <geom type="capsule" name="R_Ear_3_geom" size="0.1" fromto="0 0 0 -0.1545829176902771 0.08008980751037598 0.09064579010009766"/>
                        </body>
                      </body>
                    </body>
                    <body name="Nose" pos="-0.010121570900082588 -0.9325973987579346 -0.19159269332885742" quat="1.0 0.0 0.0 0.0">
                    <geom type="capsule" name="Nose_geom" size="0.1" fromto="0 0 0 9.313225746154785e-10 -1.112250804901123 -0.4105626344680786"/>
                    </body>
                  </body>
                </body>
                <body name="L_F_Paw_1" pos="0.0 -0.7133957147598267 -0.37315845489501953" quat="1.0 0.0 0.0 0.0">
                <joint type="hinge" name="rx_L_F_Paw_1" axis="1 0 0" range="-30.000000834826057 30.000000834826057"/>
                <joint type="hinge" name="ry_L_F_Paw_1" axis="0 1 0" range="-19.99999941818584 19.99999941818584"/>
                <joint type="hinge" name="rz_L_F_Paw_1" axis="0 0 1" range="-30.000000834826057 30.000000834826057"/>
                <geom type="capsule" name="L_F_Paw_1_geom" size="0.1" fromto="0 0 0 0.6048069000244141 0.5854717493057251 -0.48604297637939453"/>
                  <body name="L_F_Paw_2" pos="0.6048069000244141 0.5854717493057251 -0.48604297637939453" quat="1.0 0.0 0.0 0.0">
                  <joint type="hinge" name="rx_L_F_Paw_2" axis="1 0 0" range="-9.99999970909292 9.99999970909292"/>
                  <joint type="hinge" name="rz_L_F_Paw_2" axis="0 0 1" range="-45.00000125223908 45.00000125223908"/>
                  <geom type="capsule" name="L_F_Paw_2_geom" size="0.1" fromto="0 0 0 -0.04760706424713135 0.0326617956161499 -1.1593438386917114"/>
                    <body name="L_F_Paw_3" pos="-0.04760706424713135 0.0326617956161499 -1.1593438386917114" quat="1.0 0.0 0.0 0.0">
                    <geom type="capsule" name="L_F_Paw_3_geom" size="0.1" fromto="0 0 0 -0.0734916627407074 -0.4948904514312744 -0.5900286436080933"/>
                      <body name="L_F_Finger_2_1" pos="-0.0734916627407074 -0.4948904514312744 -0.5900286436080933" quat="1.0 0.0 0.0 0.0">
                      <geom type="capsule" name="L_F_Finger_2_1_geom" size="0.1" fromto="0 0 0 -0.007899433374404907 -0.19724273681640625 -0.03392493724822998"/>
                        <body name="L_F_Finger_2_2" pos="-0.007899433374404907 -0.19724273681640625 -0.03392493724822998" quat="1.0 0.0 0.0 0.0">
                        <geom type="capsule" name="L_F_Finger_2_2_geom" size="0.1" fromto="0 0 0 -0.01064792275428772 -0.18222808837890625 -0.04573908448219299"/>
                          <body name="L_F_Finger_2_3" pos="-0.01064792275428772 -0.18222808837890625 -0.04573908448219299" quat="1.0 0.0 0.0 0.0">
                          <geom type="capsule" name="L_F_Finger_2_3_geom" size="0.1" fromto="0 0 0 -0.00497928261756897 -0.12030792236328125 -0.05246439576148987"/>
                          </body>
                        </body>
                      </body>
                      <body name="L_F_Finger_3_1" pos="-0.0734916627407074 -0.4948904514312744 -0.5900286436080933" quat="1.0 0.0 0.0 0.0">
                      <geom type="capsule" name="L_F_Finger_3_1_geom" size="0.1" fromto="0 0 0 0.09537398815155029 -0.17918014526367188 -0.022127985954284668"/>
                        <body name="L_F_Finger_3_2" pos="0.09537398815155029 -0.17918014526367188 -0.022127985954284668" quat="1.0 0.0 0.0 0.0">
                        <geom type="capsule" name="L_F_Finger_3_2_geom" size="0.1" fromto="0 0 0 0.06135064363479614 -0.1559734344482422 -0.0262068510055542"/>
                          <body name="L_F_Finger_3_3" pos="0.06135064363479614 -0.1559734344482422 -0.0262068510055542" quat="1.0 0.0 0.0 0.0">
                          <geom type="capsule" name="L_F_Finger_3_3_geom" size="0.1" fromto="0 0 0 0.04648095369338989 -0.12756919860839844 -0.03816783428192139"/>
                          </body>
                        </body>
                      </body>
                      <body name="L_F_Finger_4_1" pos="-0.0734916627407074 -0.4948904514312744 -0.5900286436080933" quat="1.0 0.0 0.0 0.0">
                      <geom type="capsule" name="L_F_Finger_4_1_geom" size="0.1" fromto="0 0 0 0.15609729290008545 -0.09903717041015625 -0.09172713756561279"/>
                        <body name="L_F_Finger_4_2" pos="0.15609729290008545 -0.09903717041015625 -0.09172713756561279" quat="1.0 0.0 0.0 0.0">
                        <geom type="capsule" name="L_F_Finger_4_2_geom" size="0.1" fromto="0 0 0 0.08468610048294067 -0.07721519470214844 -0.011312365531921387"/>
                          <body name="L_F_Finger_4_3" pos="0.08468610048294067 -0.07721519470214844 -0.011312365531921387" quat="1.0 0.0 0.0 0.0">
                          <geom type="capsule" name="L_F_Finger_4_3_geom" size="0.1" fromto="0 0 0 0.0686529278755188 -0.063507080078125 -0.0367964506149292"/>
                          </body>
                        </body>
                      </body>
                      <body name="L_F_Finger_1_1" pos="-0.0734916627407074 -0.4948904514312744 -0.5900286436080933" quat="1.0 0.0 0.0 0.0">
                      <geom type="capsule" name="L_F_Finger_1_1_geom" size="0.1" fromto="0 0 0 -0.10550609230995178 -0.1405181884765625 -0.08140170574188232"/>
                        <body name="L_F_Finger_1_2" pos="-0.10550609230995178 -0.1405181884765625 -0.08140170574188232" quat="1.0 0.0 0.0 0.0">
                        <geom type="capsule" name="L_F_Finger_1_2_geom" size="0.1" fromto="0 0 0 -0.08815112709999084 -0.10850334167480469 0.00011074542999267578"/>
                          <body name="L_F_Finger_1_3" pos="-0.08815112709999084 -0.10850334167480469 0.00011074542999267578" quat="1.0 0.0 0.0 0.0">
                          <geom type="capsule" name="L_F_Finger_1_3_geom" size="0.1" fromto="0 0 0 -0.06533350050449371 -0.083648681640625 -0.03696431219577789"/>
                          </body>
                        </body>
                      </body>
                    </body>
                  </body>
                </body>
                <body name="R_F_Paw_1" pos="0.0 -0.7133957147598267 -0.37315845489501953" quat="1.0 0.0 0.0 0.0">
                <joint type="hinge" name="rx_R_F_Paw_1" axis="1 0 0" range="-30.000000834826057 30.000000834826057"/>
                <joint type="hinge" name="ry_R_F_Paw_1" axis="0 1 0" range="-19.99999941818584 19.99999941818584"/>
                <joint type="hinge" name="rz_R_F_Paw_1" axis="0 0 1" range="-30.000000834826057 30.000000834826057"/>
                <geom type="capsule" name="R_F_Paw_1_geom" size="0.1" fromto="0 0 0 -0.6048069000244141 0.5854717493057251 -0.48604297637939453"/>
                  <body name="R_F_Paw_2" pos="-0.6048069000244141 0.5854717493057251 -0.48604297637939453" quat="1.0 0.0 0.0 0.0">
                  <joint type="hinge" name="rx_R_F_Paw_2" axis="1 0 0" range="-9.99999970909292 9.99999970909292"/>
                  <joint type="hinge" name="rz_R_F_Paw_2" axis="0 0 1" range="-45.00000125223908 45.00000125223908"/>
                  <geom type="capsule" name="R_F_Paw_2_geom" size="0.1" fromto="0 0 0 0.04760706424713135 0.03266191482543945 -1.1593438386917114"/>
                    <body name="R_F_Paw_3" pos="0.04760706424713135 0.03266191482543945 -1.1593438386917114" quat="1.0 0.0 0.0 0.0">
                    <geom type="capsule" name="R_F_Paw_3_geom" size="0.1" fromto="0 0 0 0.0734916627407074 -0.49489033222198486 -0.5900287628173828"/>
                      <body name="R_F_Finger_2_1" pos="0.0734916627407074 -0.49489033222198486 -0.5900287628173828" quat="1.0 0.0 0.0 0.0">
                      <geom type="capsule" name="R_F_Finger_2_1_geom" size="0.1" fromto="0 0 0 0.007899463176727295 -0.19724273681640625 -0.03392505645751953"/>
                        <body name="R_F_Finger_2_2" pos="0.007899463176727295 -0.19724273681640625 -0.03392505645751953" quat="1.0 0.0 0.0 0.0">
                        <geom type="capsule" name="R_F_Finger_2_2_geom" size="0.1" fromto="0 0 0 0.010647952556610107 -0.18222808837890625 -0.045739173889160156"/>
                          <body name="R_F_Finger_2_3" pos="0.010647952556610107 -0.18222808837890625 -0.045739173889160156" quat="1.0 0.0 0.0 0.0">
                          <geom type="capsule" name="R_F_Finger_2_3_geom" size="0.1" fromto="0 0 0 0.004979312419891357 -0.12030792236328125 -0.05246448516845703"/>
                          </body>
                        </body>
                      </body>
                      <body name="R_F_Finger_3_1" pos="0.0734916627407074 -0.49489033222198486 -0.5900287628173828" quat="1.0 0.0 0.0 0.0">
                      <geom type="capsule" name="R_F_Finger_3_1_geom" size="0.1" fromto="0 0 0 -0.09537389874458313 -0.17918014526367188 -0.02212810516357422"/>
                        <body name="R_F_Finger_3_2" pos="-0.09537389874458313 -0.17918014526367188 -0.02212810516357422" quat="1.0 0.0 0.0 0.0">
                        <geom type="capsule" name="R_F_Finger_3_2_geom" size="0.1" fromto="0 0 0 -0.06135064363479614 -0.1559734344482422 -0.02620697021484375"/>
                          <body name="R_F_Finger_3_3" pos="-0.06135064363479614 -0.1559734344482422 -0.02620697021484375" quat="1.0 0.0 0.0 0.0">
                          <geom type="capsule" name="R_F_Finger_3_3_geom" size="0.1" fromto="0 0 0 -0.04648095369338989 -0.12756919860839844 -0.03816795349121094"/>
                          </body>
                        </body>
                      </body>
                      <body name="R_F_Finger_4_1" pos="0.0734916627407074 -0.49489033222198486 -0.5900287628173828" quat="1.0 0.0 0.0 0.0">
                      <geom type="capsule" name="R_F_Finger_4_1_geom" size="0.1" fromto="0 0 0 -0.1560972034931183 -0.09903717041015625 -0.09172725677490234"/>
                        <body name="R_F_Finger_4_2" pos="-0.1560972034931183 -0.09903717041015625 -0.09172725677490234" quat="1.0 0.0 0.0 0.0">
                        <geom type="capsule" name="R_F_Finger_4_2_geom" size="0.1" fromto="0 0 0 -0.08468610048294067 -0.07721519470214844 -0.011312469840049744"/>
                          <body name="R_F_Finger_4_3" pos="-0.08468610048294067 -0.07721519470214844 -0.011312469840049744" quat="1.0 0.0 0.0 0.0">
                          <geom type="capsule" name="R_F_Finger_4_3_geom" size="0.1" fromto="0 0 0 -0.0686529278755188 -0.063507080078125 -0.036796554923057556"/>
                          </body>
                        </body>
                      </body>
                      <body name="R_F_Finger_1_1" pos="0.0734916627407074 -0.49489033222198486 -0.5900287628173828" quat="1.0 0.0 0.0 0.0">
                      <geom type="capsule" name="R_F_Finger_1_1_geom" size="0.1" fromto="0 0 0 0.10550612211227417 -0.1405181884765625 -0.08140182495117188"/>
                        <body name="R_F_Finger_1_2" pos="0.10550612211227417 -0.1405181884765625 -0.08140182495117188" quat="1.0 0.0 0.0 0.0">
                        <geom type="capsule" name="R_F_Finger_1_2_geom" size="0.1" fromto="0 0 0 0.08815118670463562 -0.10850334167480469 0.000110626220703125"/>
                          <body name="R_F_Finger_1_3" pos="0.08815118670463562 -0.10850334167480469 0.000110626220703125" quat="1.0 0.0 0.0 0.0">
                          <geom type="capsule" name="R_F_Finger_1_3_geom" size="0.1" fromto="0 0 0 0.06533358991146088 -0.083648681640625 -0.03696441650390625"/>
                          </body>
                        </body>
                      </body>
                    </body>
                  </body>
                </body>
              </body>
            </body>
          </body>
        </body>
      </body>
      <body name="Tail_1" pos="0.0 -0.30201101303100586 -0.2969825267791748" quat="1.0 0.0 0.0 0.0">
      <joint type="hinge" name="rx_Tail_1" axis="1 0 0" range="-4.99999985454646 4.99999985454646"/>
      <joint type="hinge" name="rz_Tail_1" axis="0 0 1" range="-4.99999985454646 4.99999985454646"/>
      <geom type="capsule" name="Tail_1_geom" size="0.1" fromto="0 0 0 0.0 0.5425865650177002 -0.6549034118652344"/>
        <body name="Tail_2" pos="0.0 0.5425865650177002 -0.6549034118652344" quat="1.0 0.0 0.0 0.0">
        <joint type="hinge" name="rx_Tail_2" axis="1 0 0" range="-4.99999985454646 4.99999985454646"/>
        <joint type="hinge" name="rz_Tail_2" axis="0 0 1" range="-4.99999985454646 4.99999985454646"/>
        <geom type="capsule" name="Tail_2_geom" size="0.1" fromto="0 0 0 0.0 0.43598294258117676 -0.22396934032440186"/>
          <body name="Tail_3" pos="0.0 0.43598294258117676 -0.22396934032440186" quat="1.0 0.0 0.0 0.0">
          <joint type="hinge" name="rx_Tail_3" axis="1 0 0" range="-4.99999985454646 4.99999985454646"/>
          <joint type="hinge" name="rz_Tail_3" axis="0 0 1" range="-4.99999985454646 4.99999985454646"/>
          <geom type="capsule" name="Tail_3_geom" size="0.1" fromto="0 0 0 0.0 0.36639881134033203 -0.1942310333251953"/>
            <body name="Tail_4" pos="0.0 0.36639881134033203 -0.1942310333251953" quat="1.0 0.0 0.0 0.0">
            <joint type="hinge" name="rx_Tail_4" axis="1 0 0" range="-4.99999985454646 4.99999985454646"/>
            <joint type="hinge" name="rz_Tail_4" axis="0 0 1" range="-4.99999985454646 4.99999985454646"/>
            <geom type="capsule" name="Tail_4_geom" size="0.1" fromto="0 0 0 0.0 0.38149547576904297 -0.21759867668151855"/>
              <body name="Tail_5" pos="0.0 0.38149547576904297 -0.21759867668151855" quat="1.0 0.0 0.0 0.0">
              <joint type="hinge" name="rx_Tail_5" axis="1 0 0" range="-4.99999985454646 4.99999985454646"/>
              <joint type="hinge" name="rz_Tail_5" axis="0 0 1" range="-4.99999985454646 4.99999985454646"/>
              <geom type="capsule" name="Tail_5_geom" size="0.1" fromto="0 0 0 0.0 0.3993067741394043 -0.12997174263000488"/>
                <body name="Tail_6" pos="0.0 0.3993067741394043 -0.12997174263000488" quat="1.0 0.0 0.0 0.0">
                <joint type="hinge" name="rx_Tail_6" axis="1 0 0" range="-4.99999985454646 4.99999985454646"/>
                <joint type="hinge" name="rz_Tail_6" axis="0 0 1" range="-4.99999985454646 4.99999985454646"/>
                <geom type="capsule" name="Tail_6_geom" size="0.1" fromto="0 0 0 0.0 0.4152975082397461 -0.09793686866760254"/>
                  <body name="Tail_7" pos="0.0 0.4152975082397461 -0.09793686866760254" quat="1.0 0.0 0.0 0.0">
                  <joint type="hinge" name="rx_Tail_7" axis="1 0 0" range="-4.99999985454646 4.99999985454646"/>
                  <joint type="hinge" name="rz_Tail_7" axis="0 0 1" range="-4.99999985454646 4.99999985454646"/>
                  <geom type="capsule" name="Tail_7_geom" size="0.1" fromto="0 0 0 0.0 0.42778778076171875 -0.07238483428955078"/>
                    <body name="Tail_8" pos="0.0 0.42778778076171875 -0.07238483428955078" quat="1.0 0.0 0.0 0.0">
                    <joint type="hinge" name="rx_Tail_8" axis="1 0 0" range="-4.99999985454646 4.99999985454646"/>
                    <joint type="hinge" name="rz_Tail_8" axis="0 0 1" range="-4.99999985454646 4.99999985454646"/>
                    <geom type="capsule" name="Tail_8_geom" size="0.1" fromto="0 0 0 0.0 0.43730831146240234 -0.05338621139526367"/>
                      <body name="Tail_9" pos="0.0 0.43730831146240234 -0.05338621139526367" quat="1.0 0.0 0.0 0.0">
                      <joint type="hinge" name="rx_Tail_9" axis="1 0 0" range="-4.99999985454646 4.99999985454646"/>
                      <joint type="hinge" name="rz_Tail_9" axis="0 0 1" range="-4.99999985454646 4.99999985454646"/>
                      <geom type="capsule" name="Tail_9_geom" size="0.1" fromto="0 0 0 0.0 0.4422578811645508 -0.04423046112060547"/>
                        <body name="Tail_10" pos="0.0 0.4422578811645508 -0.04423046112060547" quat="1.0 0.0 0.0 0.0">
                        <joint type="hinge" name="rx_Tail_10" axis="1 0 0" range="-4.99999985454646 4.99999985454646"/>
                        <joint type="hinge" name="rz_Tail_10" axis="0 0 1" range="-4.99999985454646 4.99999985454646"/>
                        <geom type="capsule" name="Tail_10_geom" size="0.1" fromto="0 0 0 0.0 0.4436378479003906 -0.03749656677246094"/>
                          <body name="Tail_11" pos="0.0 0.4436378479003906 -0.03749656677246094" quat="1.0 0.0 0.0 0.0">
                          <joint type="hinge" name="rx_Tail_11" axis="1 0 0" range="-4.99999985454646 4.99999985454646"/>
                          <joint type="hinge" name="rz_Tail_11" axis="0 0 1" range="-4.99999985454646 4.99999985454646"/>
                          <geom type="capsule" name="Tail_11_geom" size="0.1" fromto="0 0 0 0.0 0.44546031951904297 -0.0318903923034668"/>
                            <body name="Tail_12" pos="0.0 0.44546031951904297 -0.0318903923034668" quat="1.0 0.0 0.0 0.0">
                            <joint type="hinge" name="rx_Tail_12" axis="1 0 0" range="-4.99999985454646 4.99999985454646"/>
                            <joint type="hinge" name="rz_Tail_12" axis="0 0 1" range="-4.99999985454646 4.99999985454646"/>
                            <geom type="capsule" name="Tail_12_geom" size="0.1" fromto="0 0 0 0.009812355041503906 0.4499988555908203 -0.02978801727294922"/>
                            </body>
                          </body>
                        </body>
                      </body>
                    </body>
                  </body>
                </body>
              </body>
            </body>
          </body>
        </body>
      </body>
      <body name="R_B_Paw_1" pos="0.0 -0.30201101303100586 -0.2969825267791748" quat="1.0 0.0 0.0 0.0">
      <joint type="hinge" name="rx_R_B_Paw_1" axis="1 0 0" range="-39.99999883637168 39.99999883637168"/>
      <joint type="hinge" name="ry_R_B_Paw_1" axis="0 1 0" range="-9.99999970909292 19.99999941818584"/>
      <joint type="hinge" name="rz_R_B_Paw_1" axis="0 0 1" range="-9.99999970909292 19.99999941818584"/>
      <geom type="capsule" name="R_B_Paw_1_geom" size="0.1" fromto="0 0 0 -0.43308162689208984 -0.7818779945373535 0.21593832969665527"/>
        <body name="R_B_Paw_2" pos="-0.43308162689208984 -0.7818779945373535 0.21593832969665527" quat="1.0 0.0 0.0 0.0">
        <joint type="hinge" name="rx_R_B_Paw_2" axis="1 0 0" range="-45.00000125223908 50.0000002530119"/>
        <joint type="hinge" name="rz_R_B_Paw_2" axis="0 0 1" range="-25.999999585151052 19.99999941818584"/>
        <geom type="capsule" name="R_B_Paw_2_geom" size="0.1" fromto="0 0 0 -0.08963388204574585 -0.04411303997039795 -0.4642941951751709"/>
          <body name="R_B_Paw_3" pos="-0.08963388204574585 -0.04411303997039795 -0.4642941951751709" quat="1.0 0.0 0.0 0.0">
          <geom type="capsule" name="R_B_Paw_3_geom" size="0.1" fromto="0 0 0 -0.24146270751953125 0.0141373872756958 -1.4100792407989502"/>
            <body name="R_B_Paw_4" pos="-0.24146270751953125 0.0141373872756958 -1.4100792407989502" quat="1.0 0.0 0.0 0.0">
            <geom type="capsule" name="R_B_Paw_4_geom" size="0.1" fromto="0 0 0 0.022909224033355713 0.13376617431640625 -0.6537196636199951"/>
              <body name="R_B_Finger_1_1" pos="0.022909224033355713 0.13376617431640625 -0.6537196636199951" quat="1.0 0.0 0.0 0.0">
              <geom type="capsule" name="R_B_Finger_1_1_geom" size="0.1" fromto="0 0 0 0.17054373025894165 -0.04652595520019531 -0.11439388990402222"/>
                <body name="R_B_Finger_1_2" pos="0.17054373025894165 -0.04652595520019531 -0.11439388990402222" quat="1.0 0.0 0.0 0.0">
                <geom type="capsule" name="R_B_Finger_1_2_geom" size="0.1" fromto="0 0 0 0.017756521701812744 -0.08623683452606201 -0.05303555727005005"/>
                  <body name="R_B_Finger_1_3" pos="0.017756521701812744 -0.08623683452606201 -0.05303555727005005" quat="1.0 0.0 0.0 0.0">
                  <geom type="capsule" name="R_B_Finger_1_3_geom" size="0.1" fromto="0 0 0 0.011121809482574463 -0.05400848388671875 -0.038996756076812744"/>
                  </body>
                </body>
              </body>
              <body name="R_B_Finger_2_1" pos="0.022909224033355713 0.13376617431640625 -0.6537196636199951" quat="1.0 0.0 0.0 0.0">
              <geom type="capsule" name="R_B_Finger_2_1_geom" size="0.1" fromto="0 0 0 0.07799345254898071 -0.13555526733398438 -0.07957440614700317"/>
                <body name="R_B_Finger_2_2" pos="0.07799345254898071 -0.13555526733398438 -0.07957440614700317" quat="1.0 0.0 0.0 0.0">
                <geom type="capsule" name="R_B_Finger_2_2_geom" size="0.1" fromto="0 0 0 0.007715284824371338 -0.22741127014160156 -0.00027364492416381836"/>
                  <body name="R_B_Finger_2_3" pos="0.007715284824371338 -0.22741127014160156 -0.00027364492416381836" quat="1.0 0.0 0.0 0.0">
                  <geom type="capsule" name="R_B_Finger_2_3_geom" size="0.1" fromto="0 0 0 0.006932318210601807 -0.15901553630828857 -0.06840777397155762"/>
                  </body>
                </body>
              </body>
              <body name="R_B_Finger_3_1" pos="0.022909224033355713 0.13376617431640625 -0.6537196636199951" quat="1.0 0.0 0.0 0.0">
              <geom type="capsule" name="R_B_Finger_3_1_geom" size="0.1" fromto="0 0 0 -0.017782151699066162 -0.13286590576171875 -0.04080277681350708"/>
                <body name="R_B_Finger_3_2" pos="-0.017782151699066162 -0.13286590576171875 -0.04080277681350708" quat="1.0 0.0 0.0 0.0">
                <geom type="capsule" name="R_B_Finger_3_2_geom" size="0.1" fromto="0 0 0 -0.052429139614105225 -0.2693747282028198 -0.06258666515350342"/>
                  <body name="R_B_Finger_3_3" pos="-0.052429139614105225 -0.2693747282028198 -0.06258666515350342" quat="1.0 0.0 0.0 0.0">
                  <geom type="capsule" name="R_B_Finger_3_3_geom" size="0.1" fromto="0 0 0 -0.025607049465179443 -0.14665794372558594 -0.06339722871780396"/>
                  </body>
                </body>
              </body>
              <body name="R_B_Finger_4_1" pos="0.022909224033355713 0.13376617431640625 -0.6537196636199951" quat="1.0 0.0 0.0 0.0">
              <geom type="capsule" name="R_B_Finger_4_1_geom" size="0.1" fromto="0 0 0 -0.09851545095443726 -0.09177780151367188 -0.06680375337600708"/>
                <body name="R_B_Finger_4_2" pos="-0.09851545095443726 -0.09177780151367188 -0.06680375337600708" quat="1.0 0.0 0.0 0.0">
                <geom type="capsule" name="R_B_Finger_4_2_geom" size="0.1" fromto="0 0 0 -0.11650842428207397 -0.23230743408203125 -0.006329476833343506"/>
                  <body name="R_B_Finger_4_3" pos="-0.11650842428207397 -0.23230743408203125 -0.006329476833343506" quat="1.0 0.0 0.0 0.0">
                  <geom type="capsule" name="R_B_Finger_4_3_geom" size="0.1" fromto="0 0 0 -0.08282470703125 -0.16325175762176514 -0.05982089042663574"/>
                  </body>
                </body>
              </body>
              <body name="R_B_Finger_5_1" pos="0.022909224033355713 0.13376617431640625 -0.6537196636199951" quat="1.0 0.0 0.0 0.0">
              <geom type="capsule" name="R_B_Finger_5_1_geom" size="0.1" fromto="0 0 0 -0.15541929006576538 0.03509712219238281 -0.12256020307540894"/>
                <body name="R_B_Finger_5_2" pos="-0.15541929006576538 0.03509712219238281 -0.12256020307540894" quat="1.0 0.0 0.0 0.0">
                <geom type="capsule" name="R_B_Finger_5_2_geom" size="0.1" fromto="0 0 0 -0.10467529296875 -0.12829971313476562 -0.017363369464874268"/>
                  <body name="R_B_Finger_5_3" pos="-0.10467529296875 -0.12829971313476562 -0.017363369464874268" quat="1.0 0.0 0.0 0.0">
                  <geom type="capsule" name="R_B_Finger_5_3_geom" size="0.1" fromto="0 0 0 -0.07809245586395264 -0.09403979778289795 -0.026294782757759094"/>
                  </body>
                </body>
              </body>
            </body>
          </body>
        </body>
      </body>
      <body name="L_B_Paw_1" pos="0.0 -0.30201101303100586 -0.2969825267791748" quat="1.0 0.0 0.0 0.0">
      <joint type="hinge" name="rx_L_B_Paw_1" axis="1 0 0" range="-39.99999883637168 39.99999883637168"/>
      <joint type="hinge" name="ry_L_B_Paw_1" axis="0 1 0" range="-9.99999970909292 19.99999941818584"/>
      <joint type="hinge" name="rz_L_B_Paw_1" axis="0 0 1" range="-19.99999941818584 9.99999970909292"/>
      <geom type="capsule" name="L_B_Paw_1_geom" size="0.1" fromto="0 0 0 0.43308162689208984 -0.7818779945373535 0.21593832969665527"/>
        <body name="L_B_Paw_2" pos="0.43308162689208984 -0.7818779945373535 0.21593832969665527" quat="1.0 0.0 0.0 0.0">
        <joint type="hinge" name="rx_L_B_Paw_2" axis="1 0 0" range="-45.00000125223908 50.0000002530119"/>
        <joint type="hinge" name="rz_L_B_Paw_2" axis="0 0 1" range="-19.99999941818584 25.999999585151052"/>
        <geom type="capsule" name="L_B_Paw_2_geom" size="0.1" fromto="0 0 0 0.08963403105735779 -0.0441131591796875 -0.4642941951751709"/>
          <body name="L_B_Paw_3" pos="0.08963403105735779 -0.0441131591796875 -0.4642941951751709" quat="1.0 0.0 0.0 0.0">
          <geom type="capsule" name="L_B_Paw_3_geom" size="0.1" fromto="0 0 0 0.24146276712417603 0.01413726806640625 -1.4100792407989502"/>
            <body name="L_B_Paw_4" pos="0.24146276712417603 0.01413726806640625 -1.4100792407989502" quat="1.0 0.0 0.0 0.0">
            <geom type="capsule" name="L_B_Paw_4_geom" size="0.1" fromto="0 0 0 -0.022909104824066162 0.1337660551071167 -0.6537197828292847"/>
              <body name="L_B_Finger_1_1" pos="-0.022909104824066162 0.1337660551071167 -0.6537197828292847" quat="1.0 0.0 0.0 0.0">
              <geom type="capsule" name="L_B_Finger_1_1_geom" size="0.1" fromto="0 0 0 -0.1705436110496521 -0.04652607440948486 -0.11439400911331177"/>
                <body name="L_B_Finger_1_2" pos="-0.1705436110496521 -0.04652607440948486 -0.11439400911331177" quat="1.0 0.0 0.0 0.0">
                <geom type="capsule" name="L_B_Finger_1_2_geom" size="0.1" fromto="0 0 0 -0.017756402492523193 -0.08623695373535156 -0.05303570628166199"/>
                  <body name="L_B_Finger_1_3" pos="-0.017756402492523193 -0.08623695373535156 -0.05303570628166199" quat="1.0 0.0 0.0 0.0">
                  <geom type="capsule" name="L_B_Finger_1_3_geom" size="0.1" fromto="0 0 0 -0.011121690273284912 -0.0540086030960083 -0.03899690508842468"/>
                  </body>
                </body>
              </body>
              <body name="L_B_Finger_2_1" pos="-0.022909104824066162 0.1337660551071167 -0.6537197828292847" quat="1.0 0.0 0.0 0.0">
              <geom type="capsule" name="L_B_Finger_2_1_geom" size="0.1" fromto="0 0 0 -0.07799333333969116 -0.13555538654327393 -0.07957452535629272"/>
                <body name="L_B_Finger_2_2" pos="-0.07799333333969116 -0.13555538654327393 -0.07957452535629272" quat="1.0 0.0 0.0 0.0">
                <geom type="capsule" name="L_B_Finger_2_2_geom" size="0.1" fromto="0 0 0 -0.007715165615081787 -0.2274113893508911 -0.00027376413345336914"/>
                  <body name="L_B_Finger_2_3" pos="-0.007715165615081787 -0.2274113893508911 -0.00027376413345336914" quat="1.0 0.0 0.0 0.0">
                  <geom type="capsule" name="L_B_Finger_2_3_geom" size="0.1" fromto="0 0 0 -0.006932199001312256 -0.15901565551757812 -0.06840789318084717"/>
                  </body>
                </body>
              </body>
              <body name="L_B_Finger_3_1" pos="-0.022909104824066162 0.1337660551071167 -0.6537197828292847" quat="1.0 0.0 0.0 0.0">
              <geom type="capsule" name="L_B_Finger_3_1_geom" size="0.1" fromto="0 0 0 0.017782270908355713 -0.1328660249710083 -0.04080289602279663"/>
                <body name="L_B_Finger_3_2" pos="0.017782270908355713 -0.1328660249710083 -0.04080289602279663" quat="1.0 0.0 0.0 0.0">
                <geom type="capsule" name="L_B_Finger_3_2_geom" size="0.1" fromto="0 0 0 0.052429258823394775 -0.2693748474121094 -0.06258678436279297"/>
                  <body name="L_B_Finger_3_3" pos="0.052429258823394775 -0.2693748474121094 -0.06258678436279297" quat="1.0 0.0 0.0 0.0">
                  <geom type="capsule" name="L_B_Finger_3_3_geom" size="0.1" fromto="0 0 0 0.025607168674468994 -0.1466580629348755 -0.0633973479270935"/>
                  </body>
                </body>
              </body>
              <body name="L_B_Finger_4_1" pos="-0.022909104824066162 0.1337660551071167 -0.6537197828292847" quat="1.0 0.0 0.0 0.0">
              <geom type="capsule" name="L_B_Finger_4_1_geom" size="0.1" fromto="0 0 0 0.0985155701637268 -0.09177792072296143 -0.06680387258529663"/>
                <body name="L_B_Finger_4_2" pos="0.0985155701637268 -0.09177792072296143 -0.06680387258529663" quat="1.0 0.0 0.0 0.0">
                <geom type="capsule" name="L_B_Finger_4_2_geom" size="0.1" fromto="0 0 0 0.11650854349136353 -0.2323075532913208 -0.006329596042633057"/>
                  <body name="L_B_Finger_4_3" pos="0.11650854349136353 -0.2323075532913208 -0.006329596042633057" quat="1.0 0.0 0.0 0.0">
                  <geom type="capsule" name="L_B_Finger_4_3_geom" size="0.1" fromto="0 0 0 0.08282470703125 -0.1632518768310547 -0.05982103943824768"/>
                  </body>
                </body>
              </body>
              <body name="L_B_Finger_5_1" pos="-0.022909104824066162 0.1337660551071167 -0.6537197828292847" quat="1.0 0.0 0.0 0.0">
              <geom type="capsule" name="L_B_Finger_5_1_geom" size="0.1" fromto="0 0 0 0.15541940927505493 0.03509700298309326 -0.12256032228469849"/>
                <body name="L_B_Finger_5_2" pos="0.15541940927505493 0.03509700298309326 -0.12256032228469849" quat="1.0 0.0 0.0 0.0">
                <geom type="capsule" name="L_B_Finger_5_2_geom" size="0.1" fromto="0 0 0 0.10467529296875 -0.12829983234405518 -0.01736348867416382"/>
                  <body name="L_B_Finger_5_3" pos="0.10467529296875 -0.12829983234405518 -0.01736348867416382" quat="1.0 0.0 0.0 0.0">
                  <geom type="capsule" name="L_B_Finger_5_3_geom" size="0.1" fromto="0 0 0 0.07809257507324219 -0.0940399169921875 -0.02629488706588745"/>
                  </body>
                </body>
              </body>
            </body>
          </body>
        </body>
      </body>
    </body>
  </worldbody>
<asset>
<texture name="grid" type="2d" builtin="checker" width="512" height="512" rgb1=".1 .2 .3" rgb2=".2 .3 .4"/>
<material name="grid" texture="grid" texrepeat="1 1" texuniform="true" reflectance=".2"/>
  </asset></mujoco>
